[2023-01-01T20:55:42.180-0300] {taskinstance.py:1087} INFO - Dependencies all met for <TaskInstance: get_interactions.join_interactions manual__2023-01-01T23:52:35.703689+00:00 [queued]>
[2023-01-01T20:55:42.196-0300] {taskinstance.py:1087} INFO - Dependencies all met for <TaskInstance: get_interactions.join_interactions manual__2023-01-01T23:52:35.703689+00:00 [queued]>
[2023-01-01T20:55:42.196-0300] {taskinstance.py:1283} INFO - 
--------------------------------------------------------------------------------
[2023-01-01T20:55:42.196-0300] {taskinstance.py:1284} INFO - Starting attempt 1 of 1
[2023-01-01T20:55:42.196-0300] {taskinstance.py:1285} INFO - 
--------------------------------------------------------------------------------
[2023-01-01T20:55:42.218-0300] {taskinstance.py:1304} INFO - Executing <Task(PythonOperator): join_interactions> on 2023-01-01 23:52:35.703689+00:00
[2023-01-01T20:55:42.224-0300] {standard_task_runner.py:55} INFO - Started process 10827 to run task
[2023-01-01T20:55:42.228-0300] {standard_task_runner.py:82} INFO - Running: ['***', 'tasks', 'run', 'get_interactions', 'join_interactions', 'manual__2023-01-01T23:52:35.703689+00:00', '--job-id', '167', '--raw', '--subdir', 'DAGS_FOLDER/get_interactions.py', '--cfg-path', '/tmp/tmpmdtwn7zd']
[2023-01-01T20:55:42.229-0300] {standard_task_runner.py:83} INFO - Job 167: Subtask join_interactions
[2023-01-01T20:55:42.311-0300] {task_command.py:389} INFO - Running <TaskInstance: get_interactions.join_interactions manual__2023-01-01T23:52:35.703689+00:00 [running]> on host kallo-Ubuntu
[2023-01-01T20:55:42.400-0300] {taskinstance.py:1513} INFO - Exporting the following env vars:
AIRFLOW_CTX_DAG_OWNER=Kallox
AIRFLOW_CTX_DAG_ID=get_interactions
AIRFLOW_CTX_TASK_ID=join_interactions
AIRFLOW_CTX_EXECUTION_DATE=2023-01-01T23:52:35.703689+00:00
AIRFLOW_CTX_TRY_NUMBER=1
AIRFLOW_CTX_DAG_RUN_ID=manual__2023-01-01T23:52:35.703689+00:00
[2023-01-01T20:55:42.406-0300] {taskinstance.py:1772} ERROR - Task failed with exception
Traceback (most recent call last):
  File "/home/kallox/anaconda3/envs/airflow/lib/python3.7/site-packages/airflow/operators/python.py", line 175, in execute
    return_value = self.execute_callable()
  File "/home/kallox/anaconda3/envs/airflow/lib/python3.7/site-packages/airflow/operators/python.py", line 192, in execute_callable
    return self.python_callable(*self.op_args, **self.op_kwargs)
  File "/home/kallox/airflow/dags/scripts/interactions/join_interactions.py", line 8, in join_interactions
    string_interactions = pd.read_csv(string_interactions_path)
  File "/home/kallox/anaconda3/envs/airflow/lib/python3.7/site-packages/pandas/util/_decorators.py", line 311, in wrapper
    return func(*args, **kwargs)
  File "/home/kallox/anaconda3/envs/airflow/lib/python3.7/site-packages/pandas/io/parsers/readers.py", line 586, in read_csv
    return _read(filepath_or_buffer, kwds)
  File "/home/kallox/anaconda3/envs/airflow/lib/python3.7/site-packages/pandas/io/parsers/readers.py", line 482, in _read
    parser = TextFileReader(filepath_or_buffer, **kwds)
  File "/home/kallox/anaconda3/envs/airflow/lib/python3.7/site-packages/pandas/io/parsers/readers.py", line 811, in __init__
    self._engine = self._make_engine(self.engine)
  File "/home/kallox/anaconda3/envs/airflow/lib/python3.7/site-packages/pandas/io/parsers/readers.py", line 1040, in _make_engine
    return mapping[engine](self.f, **self.options)  # type: ignore[call-arg]
  File "/home/kallox/anaconda3/envs/airflow/lib/python3.7/site-packages/pandas/io/parsers/c_parser_wrapper.py", line 51, in __init__
    self._open_handles(src, kwds)
  File "/home/kallox/anaconda3/envs/airflow/lib/python3.7/site-packages/pandas/io/parsers/base_parser.py", line 229, in _open_handles
    errors=kwds.get("encoding_errors", "strict"),
  File "/home/kallox/anaconda3/envs/airflow/lib/python3.7/site-packages/pandas/io/common.py", line 707, in get_handle
    newline="",
FileNotFoundError: [Errno 2] No such file or directory: './dags/files/string/interactions_uniprot_ids.csv'
[2023-01-01T20:55:42.420-0300] {taskinstance.py:1327} INFO - Marking task as FAILED. dag_id=get_interactions, task_id=join_interactions, execution_date=20230101T235235, start_date=20230101T235542, end_date=20230101T235542
[2023-01-01T20:55:42.434-0300] {standard_task_runner.py:105} ERROR - Failed to execute job 167 for task join_interactions ([Errno 2] No such file or directory: './dags/files/string/interactions_uniprot_ids.csv'; 10827)
[2023-01-01T20:55:42.478-0300] {local_task_job.py:159} INFO - Task exited with return code 1
[2023-01-01T20:55:42.519-0300] {taskinstance.py:2582} INFO - 0 downstream tasks scheduled from follow-on schedule check
