[2023-01-01T20:30:46.522-0300] {processor.py:153} INFO - Started process (PID=3611) to work on /home/kallox/airflow/dags/download_vdjdb.py
[2023-01-01T20:30:46.522-0300] {processor.py:743} INFO - Processing file /home/kallox/airflow/dags/download_vdjdb.py for tasks to queue
[2023-01-01T20:30:46.523-0300] {logging_mixin.py:137} INFO - [2023-01-01T20:30:46.523-0300] {dagbag.py:538} INFO - Filling up the DagBag from /home/kallox/airflow/dags/download_vdjdb.py
[2023-01-01T20:30:46.529-0300] {logging_mixin.py:137} INFO - [2023-01-01T20:30:46.529-0300] {dagbag.py:343} ERROR - Failed to import: /home/kallox/airflow/dags/download_vdjdb.py
Traceback (most recent call last):
  File "/home/kallox/anaconda3/envs/airflow/lib/python3.7/site-packages/airflow/models/dagbag.py", line 339, in parse
    loader.exec_module(new_module)
  File "<frozen importlib._bootstrap_external>", line 728, in exec_module
  File "<frozen importlib._bootstrap>", line 219, in _call_with_frames_removed
  File "/home/kallox/airflow/dags/download_vdjdb.py", line 15, in <module>
    download_files = PythonOperator(task_id='download_files', python_callable=download)
NameError: name 'download' is not defined
[2023-01-01T20:30:46.529-0300] {processor.py:755} WARNING - No viable dags retrieved from /home/kallox/airflow/dags/download_vdjdb.py
[2023-01-01T20:30:46.549-0300] {processor.py:175} INFO - Processing /home/kallox/airflow/dags/download_vdjdb.py took 0.029 seconds
[2023-01-01T20:31:17.581-0300] {processor.py:153} INFO - Started process (PID=4872) to work on /home/kallox/airflow/dags/download_vdjdb.py
[2023-01-01T20:31:17.582-0300] {processor.py:743} INFO - Processing file /home/kallox/airflow/dags/download_vdjdb.py for tasks to queue
[2023-01-01T20:31:17.582-0300] {logging_mixin.py:137} INFO - [2023-01-01T20:31:17.582-0300] {dagbag.py:538} INFO - Filling up the DagBag from /home/kallox/airflow/dags/download_vdjdb.py
[2023-01-01T20:31:17.594-0300] {logging_mixin.py:137} INFO - [2023-01-01T20:31:17.592-0300] {dagbag.py:343} ERROR - Failed to import: /home/kallox/airflow/dags/download_vdjdb.py
Traceback (most recent call last):
  File "/home/kallox/anaconda3/envs/airflow/lib/python3.7/site-packages/airflow/models/dagbag.py", line 339, in parse
    loader.exec_module(new_module)
  File "<frozen importlib._bootstrap_external>", line 728, in exec_module
  File "<frozen importlib._bootstrap>", line 219, in _call_with_frames_removed
  File "/home/kallox/airflow/dags/download_vdjdb.py", line 15, in <module>
    download_files = PythonOperator(task_id='download_files', python_callable=download)
NameError: name 'download' is not defined
[2023-01-01T20:31:17.594-0300] {processor.py:755} WARNING - No viable dags retrieved from /home/kallox/airflow/dags/download_vdjdb.py
[2023-01-01T20:31:17.620-0300] {processor.py:175} INFO - Processing /home/kallox/airflow/dags/download_vdjdb.py took 0.042 seconds
[2023-01-01T20:31:48.460-0300] {processor.py:153} INFO - Started process (PID=5255) to work on /home/kallox/airflow/dags/download_vdjdb.py
[2023-01-01T20:31:48.461-0300] {processor.py:743} INFO - Processing file /home/kallox/airflow/dags/download_vdjdb.py for tasks to queue
[2023-01-01T20:31:48.461-0300] {logging_mixin.py:137} INFO - [2023-01-01T20:31:48.461-0300] {dagbag.py:538} INFO - Filling up the DagBag from /home/kallox/airflow/dags/download_vdjdb.py
[2023-01-01T20:31:48.468-0300] {logging_mixin.py:137} INFO - [2023-01-01T20:31:48.467-0300] {dagbag.py:343} ERROR - Failed to import: /home/kallox/airflow/dags/download_vdjdb.py
Traceback (most recent call last):
  File "/home/kallox/anaconda3/envs/airflow/lib/python3.7/site-packages/airflow/models/dagbag.py", line 339, in parse
    loader.exec_module(new_module)
  File "<frozen importlib._bootstrap_external>", line 728, in exec_module
  File "<frozen importlib._bootstrap>", line 219, in _call_with_frames_removed
  File "/home/kallox/airflow/dags/download_vdjdb.py", line 15, in <module>
    download_files = PythonOperator(task_id='download_files', python_callable=download)
NameError: name 'download' is not defined
[2023-01-01T20:31:48.468-0300] {processor.py:755} WARNING - No viable dags retrieved from /home/kallox/airflow/dags/download_vdjdb.py
[2023-01-01T20:31:48.488-0300] {processor.py:175} INFO - Processing /home/kallox/airflow/dags/download_vdjdb.py took 0.029 seconds
[2023-01-01T20:32:18.796-0300] {processor.py:153} INFO - Started process (PID=5612) to work on /home/kallox/airflow/dags/download_vdjdb.py
[2023-01-01T20:32:18.796-0300] {processor.py:743} INFO - Processing file /home/kallox/airflow/dags/download_vdjdb.py for tasks to queue
[2023-01-01T20:32:18.797-0300] {logging_mixin.py:137} INFO - [2023-01-01T20:32:18.797-0300] {dagbag.py:538} INFO - Filling up the DagBag from /home/kallox/airflow/dags/download_vdjdb.py
[2023-01-01T20:32:18.804-0300] {logging_mixin.py:137} INFO - [2023-01-01T20:32:18.804-0300] {dagbag.py:343} ERROR - Failed to import: /home/kallox/airflow/dags/download_vdjdb.py
Traceback (most recent call last):
  File "/home/kallox/anaconda3/envs/airflow/lib/python3.7/site-packages/airflow/models/dagbag.py", line 339, in parse
    loader.exec_module(new_module)
  File "<frozen importlib._bootstrap_external>", line 728, in exec_module
  File "<frozen importlib._bootstrap>", line 219, in _call_with_frames_removed
  File "/home/kallox/airflow/dags/download_vdjdb.py", line 15, in <module>
    download_files = PythonOperator(task_id='download_files', python_callable=download)
NameError: name 'download' is not defined
[2023-01-01T20:32:18.805-0300] {processor.py:755} WARNING - No viable dags retrieved from /home/kallox/airflow/dags/download_vdjdb.py
[2023-01-01T20:32:18.827-0300] {processor.py:175} INFO - Processing /home/kallox/airflow/dags/download_vdjdb.py took 0.033 seconds
[2023-01-01T20:32:50.409-0300] {processor.py:153} INFO - Started process (PID=5926) to work on /home/kallox/airflow/dags/download_vdjdb.py
[2023-01-01T20:32:50.410-0300] {processor.py:743} INFO - Processing file /home/kallox/airflow/dags/download_vdjdb.py for tasks to queue
[2023-01-01T20:32:50.410-0300] {logging_mixin.py:137} INFO - [2023-01-01T20:32:50.410-0300] {dagbag.py:538} INFO - Filling up the DagBag from /home/kallox/airflow/dags/download_vdjdb.py
[2023-01-01T20:32:50.418-0300] {logging_mixin.py:137} INFO - [2023-01-01T20:32:50.417-0300] {dagbag.py:343} ERROR - Failed to import: /home/kallox/airflow/dags/download_vdjdb.py
Traceback (most recent call last):
  File "/home/kallox/anaconda3/envs/airflow/lib/python3.7/site-packages/airflow/models/dagbag.py", line 339, in parse
    loader.exec_module(new_module)
  File "<frozen importlib._bootstrap_external>", line 728, in exec_module
  File "<frozen importlib._bootstrap>", line 219, in _call_with_frames_removed
  File "/home/kallox/airflow/dags/download_vdjdb.py", line 15, in <module>
    download_files = PythonOperator(task_id='download_files', python_callable=download)
NameError: name 'download' is not defined
[2023-01-01T20:32:50.418-0300] {processor.py:755} WARNING - No viable dags retrieved from /home/kallox/airflow/dags/download_vdjdb.py
[2023-01-01T20:32:50.439-0300] {processor.py:175} INFO - Processing /home/kallox/airflow/dags/download_vdjdb.py took 0.032 seconds
[2023-01-01T20:33:21.281-0300] {processor.py:153} INFO - Started process (PID=6228) to work on /home/kallox/airflow/dags/download_vdjdb.py
[2023-01-01T20:33:21.281-0300] {processor.py:743} INFO - Processing file /home/kallox/airflow/dags/download_vdjdb.py for tasks to queue
[2023-01-01T20:33:21.282-0300] {logging_mixin.py:137} INFO - [2023-01-01T20:33:21.282-0300] {dagbag.py:538} INFO - Filling up the DagBag from /home/kallox/airflow/dags/download_vdjdb.py
[2023-01-01T20:33:21.288-0300] {logging_mixin.py:137} INFO - [2023-01-01T20:33:21.288-0300] {dagbag.py:343} ERROR - Failed to import: /home/kallox/airflow/dags/download_vdjdb.py
Traceback (most recent call last):
  File "/home/kallox/anaconda3/envs/airflow/lib/python3.7/site-packages/airflow/models/dagbag.py", line 339, in parse
    loader.exec_module(new_module)
  File "<frozen importlib._bootstrap_external>", line 728, in exec_module
  File "<frozen importlib._bootstrap>", line 219, in _call_with_frames_removed
  File "/home/kallox/airflow/dags/download_vdjdb.py", line 15, in <module>
    download_files = PythonOperator(task_id='download_files', python_callable=download)
NameError: name 'download' is not defined
[2023-01-01T20:33:21.288-0300] {processor.py:755} WARNING - No viable dags retrieved from /home/kallox/airflow/dags/download_vdjdb.py
[2023-01-01T20:33:21.310-0300] {processor.py:175} INFO - Processing /home/kallox/airflow/dags/download_vdjdb.py took 0.033 seconds
[2023-01-01T20:34:49.295-0300] {processor.py:153} INFO - Started process (PID=7068) to work on /home/kallox/airflow/dags/download_vdjdb.py
[2023-01-01T20:34:49.295-0300] {processor.py:743} INFO - Processing file /home/kallox/airflow/dags/download_vdjdb.py for tasks to queue
[2023-01-01T20:34:49.296-0300] {logging_mixin.py:137} INFO - [2023-01-01T20:34:49.296-0300] {dagbag.py:538} INFO - Filling up the DagBag from /home/kallox/airflow/dags/download_vdjdb.py
[2023-01-01T20:34:49.302-0300] {logging_mixin.py:137} INFO - [2023-01-01T20:34:49.301-0300] {dagbag.py:343} ERROR - Failed to import: /home/kallox/airflow/dags/download_vdjdb.py
Traceback (most recent call last):
  File "/home/kallox/anaconda3/envs/airflow/lib/python3.7/site-packages/airflow/models/dagbag.py", line 339, in parse
    loader.exec_module(new_module)
  File "<frozen importlib._bootstrap_external>", line 728, in exec_module
  File "<frozen importlib._bootstrap>", line 219, in _call_with_frames_removed
  File "/home/kallox/airflow/dags/download_vdjdb.py", line 15, in <module>
    download_files = PythonOperator(task_id='download_files', python_callable=download)
NameError: name 'download' is not defined
[2023-01-01T20:34:49.302-0300] {processor.py:755} WARNING - No viable dags retrieved from /home/kallox/airflow/dags/download_vdjdb.py
[2023-01-01T20:34:49.321-0300] {processor.py:175} INFO - Processing /home/kallox/airflow/dags/download_vdjdb.py took 0.030 seconds
[2023-01-01T20:35:20.865-0300] {processor.py:153} INFO - Started process (PID=7158) to work on /home/kallox/airflow/dags/download_vdjdb.py
[2023-01-01T20:35:20.866-0300] {processor.py:743} INFO - Processing file /home/kallox/airflow/dags/download_vdjdb.py for tasks to queue
[2023-01-01T20:35:20.866-0300] {logging_mixin.py:137} INFO - [2023-01-01T20:35:20.866-0300] {dagbag.py:538} INFO - Filling up the DagBag from /home/kallox/airflow/dags/download_vdjdb.py
[2023-01-01T20:35:20.874-0300] {logging_mixin.py:137} INFO - [2023-01-01T20:35:20.873-0300] {dagbag.py:343} ERROR - Failed to import: /home/kallox/airflow/dags/download_vdjdb.py
Traceback (most recent call last):
  File "/home/kallox/anaconda3/envs/airflow/lib/python3.7/site-packages/airflow/models/dagbag.py", line 339, in parse
    loader.exec_module(new_module)
  File "<frozen importlib._bootstrap_external>", line 728, in exec_module
  File "<frozen importlib._bootstrap>", line 219, in _call_with_frames_removed
  File "/home/kallox/airflow/dags/download_vdjdb.py", line 15, in <module>
    download_files = PythonOperator(task_id='download_files', python_callable=download)
NameError: name 'download' is not defined
[2023-01-01T20:35:20.874-0300] {processor.py:755} WARNING - No viable dags retrieved from /home/kallox/airflow/dags/download_vdjdb.py
[2023-01-01T20:35:20.896-0300] {processor.py:175} INFO - Processing /home/kallox/airflow/dags/download_vdjdb.py took 0.033 seconds
[2023-01-01T20:35:51.417-0300] {processor.py:153} INFO - Started process (PID=7237) to work on /home/kallox/airflow/dags/download_vdjdb.py
[2023-01-01T20:35:51.418-0300] {processor.py:743} INFO - Processing file /home/kallox/airflow/dags/download_vdjdb.py for tasks to queue
[2023-01-01T20:35:51.418-0300] {logging_mixin.py:137} INFO - [2023-01-01T20:35:51.418-0300] {dagbag.py:538} INFO - Filling up the DagBag from /home/kallox/airflow/dags/download_vdjdb.py
[2023-01-01T20:35:51.424-0300] {logging_mixin.py:137} INFO - [2023-01-01T20:35:51.424-0300] {dagbag.py:343} ERROR - Failed to import: /home/kallox/airflow/dags/download_vdjdb.py
Traceback (most recent call last):
  File "/home/kallox/anaconda3/envs/airflow/lib/python3.7/site-packages/airflow/models/dagbag.py", line 339, in parse
    loader.exec_module(new_module)
  File "<frozen importlib._bootstrap_external>", line 728, in exec_module
  File "<frozen importlib._bootstrap>", line 219, in _call_with_frames_removed
  File "/home/kallox/airflow/dags/download_vdjdb.py", line 15, in <module>
    download_files = PythonOperator(task_id='download_files', python_callable=download)
NameError: name 'download' is not defined
[2023-01-01T20:35:51.425-0300] {processor.py:755} WARNING - No viable dags retrieved from /home/kallox/airflow/dags/download_vdjdb.py
[2023-01-01T20:35:51.443-0300] {processor.py:175} INFO - Processing /home/kallox/airflow/dags/download_vdjdb.py took 0.028 seconds
[2023-01-01T20:36:22.080-0300] {processor.py:153} INFO - Started process (PID=7312) to work on /home/kallox/airflow/dags/download_vdjdb.py
[2023-01-01T20:36:22.085-0300] {processor.py:743} INFO - Processing file /home/kallox/airflow/dags/download_vdjdb.py for tasks to queue
[2023-01-01T20:36:22.085-0300] {logging_mixin.py:137} INFO - [2023-01-01T20:36:22.085-0300] {dagbag.py:538} INFO - Filling up the DagBag from /home/kallox/airflow/dags/download_vdjdb.py
[2023-01-01T20:36:22.094-0300] {logging_mixin.py:137} INFO - [2023-01-01T20:36:22.093-0300] {dagbag.py:343} ERROR - Failed to import: /home/kallox/airflow/dags/download_vdjdb.py
Traceback (most recent call last):
  File "/home/kallox/anaconda3/envs/airflow/lib/python3.7/site-packages/airflow/models/dagbag.py", line 339, in parse
    loader.exec_module(new_module)
  File "<frozen importlib._bootstrap_external>", line 728, in exec_module
  File "<frozen importlib._bootstrap>", line 219, in _call_with_frames_removed
  File "/home/kallox/airflow/dags/download_vdjdb.py", line 15, in <module>
    download_files = PythonOperator(task_id='download_files', python_callable=download)
NameError: name 'download' is not defined
[2023-01-01T20:36:22.094-0300] {processor.py:755} WARNING - No viable dags retrieved from /home/kallox/airflow/dags/download_vdjdb.py
[2023-01-01T20:36:22.118-0300] {processor.py:175} INFO - Processing /home/kallox/airflow/dags/download_vdjdb.py took 0.041 seconds
[2023-01-01T20:36:52.713-0300] {processor.py:153} INFO - Started process (PID=7395) to work on /home/kallox/airflow/dags/download_vdjdb.py
[2023-01-01T20:36:52.714-0300] {processor.py:743} INFO - Processing file /home/kallox/airflow/dags/download_vdjdb.py for tasks to queue
[2023-01-01T20:36:52.714-0300] {logging_mixin.py:137} INFO - [2023-01-01T20:36:52.714-0300] {dagbag.py:538} INFO - Filling up the DagBag from /home/kallox/airflow/dags/download_vdjdb.py
[2023-01-01T20:36:52.721-0300] {logging_mixin.py:137} INFO - [2023-01-01T20:36:52.720-0300] {dagbag.py:343} ERROR - Failed to import: /home/kallox/airflow/dags/download_vdjdb.py
Traceback (most recent call last):
  File "/home/kallox/anaconda3/envs/airflow/lib/python3.7/site-packages/airflow/models/dagbag.py", line 339, in parse
    loader.exec_module(new_module)
  File "<frozen importlib._bootstrap_external>", line 728, in exec_module
  File "<frozen importlib._bootstrap>", line 219, in _call_with_frames_removed
  File "/home/kallox/airflow/dags/download_vdjdb.py", line 15, in <module>
    download_files = PythonOperator(task_id='download_files', python_callable=download)
NameError: name 'download' is not defined
[2023-01-01T20:36:52.721-0300] {processor.py:755} WARNING - No viable dags retrieved from /home/kallox/airflow/dags/download_vdjdb.py
[2023-01-01T20:36:52.740-0300] {processor.py:175} INFO - Processing /home/kallox/airflow/dags/download_vdjdb.py took 0.029 seconds
[2023-01-01T20:37:23.683-0300] {processor.py:153} INFO - Started process (PID=7482) to work on /home/kallox/airflow/dags/download_vdjdb.py
[2023-01-01T20:37:23.683-0300] {processor.py:743} INFO - Processing file /home/kallox/airflow/dags/download_vdjdb.py for tasks to queue
[2023-01-01T20:37:23.684-0300] {logging_mixin.py:137} INFO - [2023-01-01T20:37:23.684-0300] {dagbag.py:538} INFO - Filling up the DagBag from /home/kallox/airflow/dags/download_vdjdb.py
[2023-01-01T20:37:23.692-0300] {logging_mixin.py:137} INFO - [2023-01-01T20:37:23.691-0300] {dagbag.py:343} ERROR - Failed to import: /home/kallox/airflow/dags/download_vdjdb.py
Traceback (most recent call last):
  File "/home/kallox/anaconda3/envs/airflow/lib/python3.7/site-packages/airflow/models/dagbag.py", line 339, in parse
    loader.exec_module(new_module)
  File "<frozen importlib._bootstrap_external>", line 728, in exec_module
  File "<frozen importlib._bootstrap>", line 219, in _call_with_frames_removed
  File "/home/kallox/airflow/dags/download_vdjdb.py", line 15, in <module>
    download_files = PythonOperator(task_id='download_files', python_callable=download)
NameError: name 'download' is not defined
[2023-01-01T20:37:23.692-0300] {processor.py:755} WARNING - No viable dags retrieved from /home/kallox/airflow/dags/download_vdjdb.py
[2023-01-01T20:37:23.717-0300] {processor.py:175} INFO - Processing /home/kallox/airflow/dags/download_vdjdb.py took 0.037 seconds
[2023-01-01T20:37:54.415-0300] {processor.py:153} INFO - Started process (PID=7558) to work on /home/kallox/airflow/dags/download_vdjdb.py
[2023-01-01T20:37:54.416-0300] {processor.py:743} INFO - Processing file /home/kallox/airflow/dags/download_vdjdb.py for tasks to queue
[2023-01-01T20:37:54.417-0300] {logging_mixin.py:137} INFO - [2023-01-01T20:37:54.417-0300] {dagbag.py:538} INFO - Filling up the DagBag from /home/kallox/airflow/dags/download_vdjdb.py
[2023-01-01T20:37:54.426-0300] {logging_mixin.py:137} INFO - [2023-01-01T20:37:54.426-0300] {dagbag.py:343} ERROR - Failed to import: /home/kallox/airflow/dags/download_vdjdb.py
Traceback (most recent call last):
  File "/home/kallox/anaconda3/envs/airflow/lib/python3.7/site-packages/airflow/models/dagbag.py", line 339, in parse
    loader.exec_module(new_module)
  File "<frozen importlib._bootstrap_external>", line 728, in exec_module
  File "<frozen importlib._bootstrap>", line 219, in _call_with_frames_removed
  File "/home/kallox/airflow/dags/download_vdjdb.py", line 15, in <module>
    download_files = PythonOperator(task_id='download_files', python_callable=download)
NameError: name 'download' is not defined
[2023-01-01T20:37:54.427-0300] {processor.py:755} WARNING - No viable dags retrieved from /home/kallox/airflow/dags/download_vdjdb.py
[2023-01-01T20:37:54.455-0300] {processor.py:175} INFO - Processing /home/kallox/airflow/dags/download_vdjdb.py took 0.043 seconds
[2023-01-01T20:38:25.027-0300] {processor.py:153} INFO - Started process (PID=7637) to work on /home/kallox/airflow/dags/download_vdjdb.py
[2023-01-01T20:38:25.028-0300] {processor.py:743} INFO - Processing file /home/kallox/airflow/dags/download_vdjdb.py for tasks to queue
[2023-01-01T20:38:25.029-0300] {logging_mixin.py:137} INFO - [2023-01-01T20:38:25.029-0300] {dagbag.py:538} INFO - Filling up the DagBag from /home/kallox/airflow/dags/download_vdjdb.py
[2023-01-01T20:38:25.036-0300] {logging_mixin.py:137} INFO - [2023-01-01T20:38:25.035-0300] {dagbag.py:343} ERROR - Failed to import: /home/kallox/airflow/dags/download_vdjdb.py
Traceback (most recent call last):
  File "/home/kallox/anaconda3/envs/airflow/lib/python3.7/site-packages/airflow/models/dagbag.py", line 339, in parse
    loader.exec_module(new_module)
  File "<frozen importlib._bootstrap_external>", line 728, in exec_module
  File "<frozen importlib._bootstrap>", line 219, in _call_with_frames_removed
  File "/home/kallox/airflow/dags/download_vdjdb.py", line 15, in <module>
    download_files = PythonOperator(task_id='download_files', python_callable=download)
NameError: name 'download' is not defined
[2023-01-01T20:38:25.036-0300] {processor.py:755} WARNING - No viable dags retrieved from /home/kallox/airflow/dags/download_vdjdb.py
[2023-01-01T20:38:25.054-0300] {processor.py:175} INFO - Processing /home/kallox/airflow/dags/download_vdjdb.py took 0.029 seconds
[2023-01-01T20:38:55.643-0300] {processor.py:153} INFO - Started process (PID=7721) to work on /home/kallox/airflow/dags/download_vdjdb.py
[2023-01-01T20:38:55.644-0300] {processor.py:743} INFO - Processing file /home/kallox/airflow/dags/download_vdjdb.py for tasks to queue
[2023-01-01T20:38:55.645-0300] {logging_mixin.py:137} INFO - [2023-01-01T20:38:55.645-0300] {dagbag.py:538} INFO - Filling up the DagBag from /home/kallox/airflow/dags/download_vdjdb.py
[2023-01-01T20:38:55.651-0300] {logging_mixin.py:137} INFO - [2023-01-01T20:38:55.650-0300] {dagbag.py:343} ERROR - Failed to import: /home/kallox/airflow/dags/download_vdjdb.py
Traceback (most recent call last):
  File "/home/kallox/anaconda3/envs/airflow/lib/python3.7/site-packages/airflow/models/dagbag.py", line 339, in parse
    loader.exec_module(new_module)
  File "<frozen importlib._bootstrap_external>", line 728, in exec_module
  File "<frozen importlib._bootstrap>", line 219, in _call_with_frames_removed
  File "/home/kallox/airflow/dags/download_vdjdb.py", line 15, in <module>
    download_files = PythonOperator(task_id='download_files', python_callable=download)
NameError: name 'download' is not defined
[2023-01-01T20:38:55.651-0300] {processor.py:755} WARNING - No viable dags retrieved from /home/kallox/airflow/dags/download_vdjdb.py
[2023-01-01T20:38:55.673-0300] {processor.py:175} INFO - Processing /home/kallox/airflow/dags/download_vdjdb.py took 0.032 seconds
[2023-01-01T20:39:26.195-0300] {processor.py:153} INFO - Started process (PID=7797) to work on /home/kallox/airflow/dags/download_vdjdb.py
[2023-01-01T20:39:26.196-0300] {processor.py:743} INFO - Processing file /home/kallox/airflow/dags/download_vdjdb.py for tasks to queue
[2023-01-01T20:39:26.196-0300] {logging_mixin.py:137} INFO - [2023-01-01T20:39:26.196-0300] {dagbag.py:538} INFO - Filling up the DagBag from /home/kallox/airflow/dags/download_vdjdb.py
[2023-01-01T20:39:26.204-0300] {logging_mixin.py:137} INFO - [2023-01-01T20:39:26.203-0300] {dagbag.py:343} ERROR - Failed to import: /home/kallox/airflow/dags/download_vdjdb.py
Traceback (most recent call last):
  File "/home/kallox/anaconda3/envs/airflow/lib/python3.7/site-packages/airflow/models/dagbag.py", line 339, in parse
    loader.exec_module(new_module)
  File "<frozen importlib._bootstrap_external>", line 728, in exec_module
  File "<frozen importlib._bootstrap>", line 219, in _call_with_frames_removed
  File "/home/kallox/airflow/dags/download_vdjdb.py", line 15, in <module>
    download_files = PythonOperator(task_id='download_files', python_callable=download)
NameError: name 'download' is not defined
[2023-01-01T20:39:26.204-0300] {processor.py:755} WARNING - No viable dags retrieved from /home/kallox/airflow/dags/download_vdjdb.py
[2023-01-01T20:39:26.224-0300] {processor.py:175} INFO - Processing /home/kallox/airflow/dags/download_vdjdb.py took 0.032 seconds
[2023-01-01T20:39:57.040-0300] {processor.py:153} INFO - Started process (PID=7873) to work on /home/kallox/airflow/dags/download_vdjdb.py
[2023-01-01T20:39:57.041-0300] {processor.py:743} INFO - Processing file /home/kallox/airflow/dags/download_vdjdb.py for tasks to queue
[2023-01-01T20:39:57.042-0300] {logging_mixin.py:137} INFO - [2023-01-01T20:39:57.041-0300] {dagbag.py:538} INFO - Filling up the DagBag from /home/kallox/airflow/dags/download_vdjdb.py
[2023-01-01T20:39:57.049-0300] {logging_mixin.py:137} INFO - [2023-01-01T20:39:57.048-0300] {dagbag.py:343} ERROR - Failed to import: /home/kallox/airflow/dags/download_vdjdb.py
Traceback (most recent call last):
  File "/home/kallox/anaconda3/envs/airflow/lib/python3.7/site-packages/airflow/models/dagbag.py", line 339, in parse
    loader.exec_module(new_module)
  File "<frozen importlib._bootstrap_external>", line 728, in exec_module
  File "<frozen importlib._bootstrap>", line 219, in _call_with_frames_removed
  File "/home/kallox/airflow/dags/download_vdjdb.py", line 15, in <module>
    download_files = PythonOperator(task_id='download_files', python_callable=download)
NameError: name 'download' is not defined
[2023-01-01T20:39:57.049-0300] {processor.py:755} WARNING - No viable dags retrieved from /home/kallox/airflow/dags/download_vdjdb.py
[2023-01-01T20:39:57.071-0300] {processor.py:175} INFO - Processing /home/kallox/airflow/dags/download_vdjdb.py took 0.034 seconds
[2023-01-01T20:40:27.628-0300] {processor.py:153} INFO - Started process (PID=7953) to work on /home/kallox/airflow/dags/download_vdjdb.py
[2023-01-01T20:40:27.629-0300] {processor.py:743} INFO - Processing file /home/kallox/airflow/dags/download_vdjdb.py for tasks to queue
[2023-01-01T20:40:27.630-0300] {logging_mixin.py:137} INFO - [2023-01-01T20:40:27.629-0300] {dagbag.py:538} INFO - Filling up the DagBag from /home/kallox/airflow/dags/download_vdjdb.py
[2023-01-01T20:40:27.636-0300] {logging_mixin.py:137} INFO - [2023-01-01T20:40:27.635-0300] {dagbag.py:343} ERROR - Failed to import: /home/kallox/airflow/dags/download_vdjdb.py
Traceback (most recent call last):
  File "/home/kallox/anaconda3/envs/airflow/lib/python3.7/site-packages/airflow/models/dagbag.py", line 339, in parse
    loader.exec_module(new_module)
  File "<frozen importlib._bootstrap_external>", line 728, in exec_module
  File "<frozen importlib._bootstrap>", line 219, in _call_with_frames_removed
  File "/home/kallox/airflow/dags/download_vdjdb.py", line 15, in <module>
    download_files = PythonOperator(task_id='download_files', python_callable=download)
NameError: name 'download' is not defined
[2023-01-01T20:40:27.636-0300] {processor.py:755} WARNING - No viable dags retrieved from /home/kallox/airflow/dags/download_vdjdb.py
[2023-01-01T20:40:27.654-0300] {processor.py:175} INFO - Processing /home/kallox/airflow/dags/download_vdjdb.py took 0.028 seconds
[2023-01-01T20:40:58.183-0300] {processor.py:153} INFO - Started process (PID=8034) to work on /home/kallox/airflow/dags/download_vdjdb.py
[2023-01-01T20:40:58.184-0300] {processor.py:743} INFO - Processing file /home/kallox/airflow/dags/download_vdjdb.py for tasks to queue
[2023-01-01T20:40:58.184-0300] {logging_mixin.py:137} INFO - [2023-01-01T20:40:58.184-0300] {dagbag.py:538} INFO - Filling up the DagBag from /home/kallox/airflow/dags/download_vdjdb.py
[2023-01-01T20:40:58.191-0300] {logging_mixin.py:137} INFO - [2023-01-01T20:40:58.191-0300] {dagbag.py:343} ERROR - Failed to import: /home/kallox/airflow/dags/download_vdjdb.py
Traceback (most recent call last):
  File "/home/kallox/anaconda3/envs/airflow/lib/python3.7/site-packages/airflow/models/dagbag.py", line 339, in parse
    loader.exec_module(new_module)
  File "<frozen importlib._bootstrap_external>", line 728, in exec_module
  File "<frozen importlib._bootstrap>", line 219, in _call_with_frames_removed
  File "/home/kallox/airflow/dags/download_vdjdb.py", line 15, in <module>
    download_files = PythonOperator(task_id='download_files', python_callable=download)
NameError: name 'download' is not defined
[2023-01-01T20:40:58.192-0300] {processor.py:755} WARNING - No viable dags retrieved from /home/kallox/airflow/dags/download_vdjdb.py
[2023-01-01T20:40:58.210-0300] {processor.py:175} INFO - Processing /home/kallox/airflow/dags/download_vdjdb.py took 0.030 seconds
[2023-01-01T20:41:28.863-0300] {processor.py:153} INFO - Started process (PID=8107) to work on /home/kallox/airflow/dags/download_vdjdb.py
[2023-01-01T20:41:28.864-0300] {processor.py:743} INFO - Processing file /home/kallox/airflow/dags/download_vdjdb.py for tasks to queue
[2023-01-01T20:41:28.865-0300] {logging_mixin.py:137} INFO - [2023-01-01T20:41:28.864-0300] {dagbag.py:538} INFO - Filling up the DagBag from /home/kallox/airflow/dags/download_vdjdb.py
[2023-01-01T20:41:28.872-0300] {logging_mixin.py:137} INFO - [2023-01-01T20:41:28.871-0300] {dagbag.py:343} ERROR - Failed to import: /home/kallox/airflow/dags/download_vdjdb.py
Traceback (most recent call last):
  File "/home/kallox/anaconda3/envs/airflow/lib/python3.7/site-packages/airflow/models/dagbag.py", line 339, in parse
    loader.exec_module(new_module)
  File "<frozen importlib._bootstrap_external>", line 728, in exec_module
  File "<frozen importlib._bootstrap>", line 219, in _call_with_frames_removed
  File "/home/kallox/airflow/dags/download_vdjdb.py", line 15, in <module>
    download_files = PythonOperator(task_id='download_files', python_callable=download)
NameError: name 'download' is not defined
[2023-01-01T20:41:28.872-0300] {processor.py:755} WARNING - No viable dags retrieved from /home/kallox/airflow/dags/download_vdjdb.py
[2023-01-01T20:41:28.895-0300] {processor.py:175} INFO - Processing /home/kallox/airflow/dags/download_vdjdb.py took 0.034 seconds
[2023-01-01T20:41:59.538-0300] {processor.py:153} INFO - Started process (PID=8196) to work on /home/kallox/airflow/dags/download_vdjdb.py
[2023-01-01T20:41:59.549-0300] {processor.py:743} INFO - Processing file /home/kallox/airflow/dags/download_vdjdb.py for tasks to queue
[2023-01-01T20:41:59.549-0300] {logging_mixin.py:137} INFO - [2023-01-01T20:41:59.549-0300] {dagbag.py:538} INFO - Filling up the DagBag from /home/kallox/airflow/dags/download_vdjdb.py
[2023-01-01T20:41:59.555-0300] {logging_mixin.py:137} INFO - [2023-01-01T20:41:59.555-0300] {dagbag.py:343} ERROR - Failed to import: /home/kallox/airflow/dags/download_vdjdb.py
Traceback (most recent call last):
  File "/home/kallox/anaconda3/envs/airflow/lib/python3.7/site-packages/airflow/models/dagbag.py", line 339, in parse
    loader.exec_module(new_module)
  File "<frozen importlib._bootstrap_external>", line 728, in exec_module
  File "<frozen importlib._bootstrap>", line 219, in _call_with_frames_removed
  File "/home/kallox/airflow/dags/download_vdjdb.py", line 15, in <module>
    download_files = PythonOperator(task_id='download_files', python_callable=download)
NameError: name 'download' is not defined
[2023-01-01T20:41:59.556-0300] {processor.py:755} WARNING - No viable dags retrieved from /home/kallox/airflow/dags/download_vdjdb.py
[2023-01-01T20:41:59.575-0300] {processor.py:175} INFO - Processing /home/kallox/airflow/dags/download_vdjdb.py took 0.039 seconds
[2023-01-01T20:42:29.936-0300] {processor.py:153} INFO - Started process (PID=8301) to work on /home/kallox/airflow/dags/download_vdjdb.py
[2023-01-01T20:42:29.936-0300] {processor.py:743} INFO - Processing file /home/kallox/airflow/dags/download_vdjdb.py for tasks to queue
[2023-01-01T20:42:29.937-0300] {logging_mixin.py:137} INFO - [2023-01-01T20:42:29.937-0300] {dagbag.py:538} INFO - Filling up the DagBag from /home/kallox/airflow/dags/download_vdjdb.py
[2023-01-01T20:42:29.943-0300] {logging_mixin.py:137} INFO - [2023-01-01T20:42:29.943-0300] {dagbag.py:343} ERROR - Failed to import: /home/kallox/airflow/dags/download_vdjdb.py
Traceback (most recent call last):
  File "/home/kallox/anaconda3/envs/airflow/lib/python3.7/site-packages/airflow/models/dagbag.py", line 339, in parse
    loader.exec_module(new_module)
  File "<frozen importlib._bootstrap_external>", line 728, in exec_module
  File "<frozen importlib._bootstrap>", line 219, in _call_with_frames_removed
  File "/home/kallox/airflow/dags/download_vdjdb.py", line 15, in <module>
    download_files = PythonOperator(task_id='download_files', python_callable=download)
NameError: name 'download' is not defined
[2023-01-01T20:42:29.944-0300] {processor.py:755} WARNING - No viable dags retrieved from /home/kallox/airflow/dags/download_vdjdb.py
[2023-01-01T20:42:29.963-0300] {processor.py:175} INFO - Processing /home/kallox/airflow/dags/download_vdjdb.py took 0.029 seconds
[2023-01-01T20:43:00.583-0300] {processor.py:153} INFO - Started process (PID=8377) to work on /home/kallox/airflow/dags/download_vdjdb.py
[2023-01-01T20:43:00.583-0300] {processor.py:743} INFO - Processing file /home/kallox/airflow/dags/download_vdjdb.py for tasks to queue
[2023-01-01T20:43:00.584-0300] {logging_mixin.py:137} INFO - [2023-01-01T20:43:00.584-0300] {dagbag.py:538} INFO - Filling up the DagBag from /home/kallox/airflow/dags/download_vdjdb.py
[2023-01-01T20:43:00.590-0300] {logging_mixin.py:137} INFO - [2023-01-01T20:43:00.590-0300] {dagbag.py:343} ERROR - Failed to import: /home/kallox/airflow/dags/download_vdjdb.py
Traceback (most recent call last):
  File "/home/kallox/anaconda3/envs/airflow/lib/python3.7/site-packages/airflow/models/dagbag.py", line 339, in parse
    loader.exec_module(new_module)
  File "<frozen importlib._bootstrap_external>", line 728, in exec_module
  File "<frozen importlib._bootstrap>", line 219, in _call_with_frames_removed
  File "/home/kallox/airflow/dags/download_vdjdb.py", line 15, in <module>
    download_files = PythonOperator(task_id='download_files', python_callable=download)
NameError: name 'download' is not defined
[2023-01-01T20:43:00.591-0300] {processor.py:755} WARNING - No viable dags retrieved from /home/kallox/airflow/dags/download_vdjdb.py
[2023-01-01T20:43:00.609-0300] {processor.py:175} INFO - Processing /home/kallox/airflow/dags/download_vdjdb.py took 0.029 seconds
[2023-01-01T20:43:31.222-0300] {processor.py:153} INFO - Started process (PID=8451) to work on /home/kallox/airflow/dags/download_vdjdb.py
[2023-01-01T20:43:31.222-0300] {processor.py:743} INFO - Processing file /home/kallox/airflow/dags/download_vdjdb.py for tasks to queue
[2023-01-01T20:43:31.223-0300] {logging_mixin.py:137} INFO - [2023-01-01T20:43:31.223-0300] {dagbag.py:538} INFO - Filling up the DagBag from /home/kallox/airflow/dags/download_vdjdb.py
[2023-01-01T20:43:31.230-0300] {logging_mixin.py:137} INFO - [2023-01-01T20:43:31.229-0300] {dagbag.py:343} ERROR - Failed to import: /home/kallox/airflow/dags/download_vdjdb.py
Traceback (most recent call last):
  File "/home/kallox/anaconda3/envs/airflow/lib/python3.7/site-packages/airflow/models/dagbag.py", line 339, in parse
    loader.exec_module(new_module)
  File "<frozen importlib._bootstrap_external>", line 728, in exec_module
  File "<frozen importlib._bootstrap>", line 219, in _call_with_frames_removed
  File "/home/kallox/airflow/dags/download_vdjdb.py", line 15, in <module>
    download_files = PythonOperator(task_id='download_files', python_callable=download)
NameError: name 'download' is not defined
[2023-01-01T20:43:31.230-0300] {processor.py:755} WARNING - No viable dags retrieved from /home/kallox/airflow/dags/download_vdjdb.py
[2023-01-01T20:43:31.249-0300] {processor.py:175} INFO - Processing /home/kallox/airflow/dags/download_vdjdb.py took 0.029 seconds
[2023-01-01T20:44:01.851-0300] {processor.py:153} INFO - Started process (PID=8540) to work on /home/kallox/airflow/dags/download_vdjdb.py
[2023-01-01T20:44:01.852-0300] {processor.py:743} INFO - Processing file /home/kallox/airflow/dags/download_vdjdb.py for tasks to queue
[2023-01-01T20:44:01.852-0300] {logging_mixin.py:137} INFO - [2023-01-01T20:44:01.852-0300] {dagbag.py:538} INFO - Filling up the DagBag from /home/kallox/airflow/dags/download_vdjdb.py
[2023-01-01T20:44:01.859-0300] {logging_mixin.py:137} INFO - [2023-01-01T20:44:01.858-0300] {dagbag.py:343} ERROR - Failed to import: /home/kallox/airflow/dags/download_vdjdb.py
Traceback (most recent call last):
  File "/home/kallox/anaconda3/envs/airflow/lib/python3.7/site-packages/airflow/models/dagbag.py", line 339, in parse
    loader.exec_module(new_module)
  File "<frozen importlib._bootstrap_external>", line 728, in exec_module
  File "<frozen importlib._bootstrap>", line 219, in _call_with_frames_removed
  File "/home/kallox/airflow/dags/download_vdjdb.py", line 15, in <module>
    download_files = PythonOperator(task_id='download_files', python_callable=download)
NameError: name 'download' is not defined
[2023-01-01T20:44:01.859-0300] {processor.py:755} WARNING - No viable dags retrieved from /home/kallox/airflow/dags/download_vdjdb.py
[2023-01-01T20:44:01.879-0300] {processor.py:175} INFO - Processing /home/kallox/airflow/dags/download_vdjdb.py took 0.031 seconds
[2023-01-01T20:44:32.422-0300] {processor.py:153} INFO - Started process (PID=8639) to work on /home/kallox/airflow/dags/download_vdjdb.py
[2023-01-01T20:44:32.423-0300] {processor.py:743} INFO - Processing file /home/kallox/airflow/dags/download_vdjdb.py for tasks to queue
[2023-01-01T20:44:32.423-0300] {logging_mixin.py:137} INFO - [2023-01-01T20:44:32.423-0300] {dagbag.py:538} INFO - Filling up the DagBag from /home/kallox/airflow/dags/download_vdjdb.py
[2023-01-01T20:44:32.430-0300] {logging_mixin.py:137} INFO - [2023-01-01T20:44:32.429-0300] {dagbag.py:343} ERROR - Failed to import: /home/kallox/airflow/dags/download_vdjdb.py
Traceback (most recent call last):
  File "/home/kallox/anaconda3/envs/airflow/lib/python3.7/site-packages/airflow/models/dagbag.py", line 339, in parse
    loader.exec_module(new_module)
  File "<frozen importlib._bootstrap_external>", line 728, in exec_module
  File "<frozen importlib._bootstrap>", line 219, in _call_with_frames_removed
  File "/home/kallox/airflow/dags/download_vdjdb.py", line 15, in <module>
    download_files = PythonOperator(task_id='download_files', python_callable=download)
NameError: name 'download' is not defined
[2023-01-01T20:44:32.430-0300] {processor.py:755} WARNING - No viable dags retrieved from /home/kallox/airflow/dags/download_vdjdb.py
[2023-01-01T20:44:32.450-0300] {processor.py:175} INFO - Processing /home/kallox/airflow/dags/download_vdjdb.py took 0.030 seconds
[2023-01-01T20:45:03.054-0300] {processor.py:153} INFO - Started process (PID=8717) to work on /home/kallox/airflow/dags/download_vdjdb.py
[2023-01-01T20:45:03.054-0300] {processor.py:743} INFO - Processing file /home/kallox/airflow/dags/download_vdjdb.py for tasks to queue
[2023-01-01T20:45:03.055-0300] {logging_mixin.py:137} INFO - [2023-01-01T20:45:03.055-0300] {dagbag.py:538} INFO - Filling up the DagBag from /home/kallox/airflow/dags/download_vdjdb.py
[2023-01-01T20:45:03.061-0300] {logging_mixin.py:137} INFO - [2023-01-01T20:45:03.061-0300] {dagbag.py:343} ERROR - Failed to import: /home/kallox/airflow/dags/download_vdjdb.py
Traceback (most recent call last):
  File "/home/kallox/anaconda3/envs/airflow/lib/python3.7/site-packages/airflow/models/dagbag.py", line 339, in parse
    loader.exec_module(new_module)
  File "<frozen importlib._bootstrap_external>", line 728, in exec_module
  File "<frozen importlib._bootstrap>", line 219, in _call_with_frames_removed
  File "/home/kallox/airflow/dags/download_vdjdb.py", line 15, in <module>
    download_files = PythonOperator(task_id='download_files', python_callable=download)
NameError: name 'download' is not defined
[2023-01-01T20:45:03.062-0300] {processor.py:755} WARNING - No viable dags retrieved from /home/kallox/airflow/dags/download_vdjdb.py
[2023-01-01T20:45:03.081-0300] {processor.py:175} INFO - Processing /home/kallox/airflow/dags/download_vdjdb.py took 0.029 seconds
[2023-01-01T20:45:34.397-0300] {processor.py:153} INFO - Started process (PID=8808) to work on /home/kallox/airflow/dags/download_vdjdb.py
[2023-01-01T20:45:34.398-0300] {processor.py:743} INFO - Processing file /home/kallox/airflow/dags/download_vdjdb.py for tasks to queue
[2023-01-01T20:45:34.398-0300] {logging_mixin.py:137} INFO - [2023-01-01T20:45:34.398-0300] {dagbag.py:538} INFO - Filling up the DagBag from /home/kallox/airflow/dags/download_vdjdb.py
[2023-01-01T20:45:34.405-0300] {logging_mixin.py:137} INFO - [2023-01-01T20:45:34.404-0300] {dagbag.py:343} ERROR - Failed to import: /home/kallox/airflow/dags/download_vdjdb.py
Traceback (most recent call last):
  File "/home/kallox/anaconda3/envs/airflow/lib/python3.7/site-packages/airflow/models/dagbag.py", line 339, in parse
    loader.exec_module(new_module)
  File "<frozen importlib._bootstrap_external>", line 728, in exec_module
  File "<frozen importlib._bootstrap>", line 219, in _call_with_frames_removed
  File "/home/kallox/airflow/dags/download_vdjdb.py", line 15, in <module>
    download_files = PythonOperator(task_id='download_files', python_callable=download)
NameError: name 'download' is not defined
[2023-01-01T20:45:34.405-0300] {processor.py:755} WARNING - No viable dags retrieved from /home/kallox/airflow/dags/download_vdjdb.py
[2023-01-01T20:45:34.424-0300] {processor.py:175} INFO - Processing /home/kallox/airflow/dags/download_vdjdb.py took 0.029 seconds
[2023-01-01T20:46:05.869-0300] {processor.py:153} INFO - Started process (PID=8897) to work on /home/kallox/airflow/dags/download_vdjdb.py
[2023-01-01T20:46:05.869-0300] {processor.py:743} INFO - Processing file /home/kallox/airflow/dags/download_vdjdb.py for tasks to queue
[2023-01-01T20:46:05.870-0300] {logging_mixin.py:137} INFO - [2023-01-01T20:46:05.870-0300] {dagbag.py:538} INFO - Filling up the DagBag from /home/kallox/airflow/dags/download_vdjdb.py
[2023-01-01T20:46:05.876-0300] {logging_mixin.py:137} INFO - [2023-01-01T20:46:05.876-0300] {dagbag.py:343} ERROR - Failed to import: /home/kallox/airflow/dags/download_vdjdb.py
Traceback (most recent call last):
  File "/home/kallox/anaconda3/envs/airflow/lib/python3.7/site-packages/airflow/models/dagbag.py", line 339, in parse
    loader.exec_module(new_module)
  File "<frozen importlib._bootstrap_external>", line 728, in exec_module
  File "<frozen importlib._bootstrap>", line 219, in _call_with_frames_removed
  File "/home/kallox/airflow/dags/download_vdjdb.py", line 15, in <module>
    download_files = PythonOperator(task_id='download_files', python_callable=download)
NameError: name 'download' is not defined
[2023-01-01T20:46:05.877-0300] {processor.py:755} WARNING - No viable dags retrieved from /home/kallox/airflow/dags/download_vdjdb.py
[2023-01-01T20:46:05.896-0300] {processor.py:175} INFO - Processing /home/kallox/airflow/dags/download_vdjdb.py took 0.029 seconds
[2023-01-01T20:46:37.595-0300] {processor.py:153} INFO - Started process (PID=8988) to work on /home/kallox/airflow/dags/download_vdjdb.py
[2023-01-01T20:46:37.596-0300] {processor.py:743} INFO - Processing file /home/kallox/airflow/dags/download_vdjdb.py for tasks to queue
[2023-01-01T20:46:37.596-0300] {logging_mixin.py:137} INFO - [2023-01-01T20:46:37.596-0300] {dagbag.py:538} INFO - Filling up the DagBag from /home/kallox/airflow/dags/download_vdjdb.py
[2023-01-01T20:46:37.605-0300] {logging_mixin.py:137} INFO - [2023-01-01T20:46:37.604-0300] {dagbag.py:343} ERROR - Failed to import: /home/kallox/airflow/dags/download_vdjdb.py
Traceback (most recent call last):
  File "/home/kallox/anaconda3/envs/airflow/lib/python3.7/site-packages/airflow/models/dagbag.py", line 339, in parse
    loader.exec_module(new_module)
  File "<frozen importlib._bootstrap_external>", line 728, in exec_module
  File "<frozen importlib._bootstrap>", line 219, in _call_with_frames_removed
  File "/home/kallox/airflow/dags/download_vdjdb.py", line 15, in <module>
    download_files = PythonOperator(task_id='download_files', python_callable=download)
NameError: name 'download' is not defined
[2023-01-01T20:46:37.605-0300] {processor.py:755} WARNING - No viable dags retrieved from /home/kallox/airflow/dags/download_vdjdb.py
[2023-01-01T20:46:37.626-0300] {processor.py:175} INFO - Processing /home/kallox/airflow/dags/download_vdjdb.py took 0.034 seconds
[2023-01-01T20:47:09.021-0300] {processor.py:153} INFO - Started process (PID=9075) to work on /home/kallox/airflow/dags/download_vdjdb.py
[2023-01-01T20:47:09.022-0300] {processor.py:743} INFO - Processing file /home/kallox/airflow/dags/download_vdjdb.py for tasks to queue
[2023-01-01T20:47:09.022-0300] {logging_mixin.py:137} INFO - [2023-01-01T20:47:09.022-0300] {dagbag.py:538} INFO - Filling up the DagBag from /home/kallox/airflow/dags/download_vdjdb.py
[2023-01-01T20:47:09.030-0300] {logging_mixin.py:137} INFO - [2023-01-01T20:47:09.030-0300] {dagbag.py:343} ERROR - Failed to import: /home/kallox/airflow/dags/download_vdjdb.py
Traceback (most recent call last):
  File "/home/kallox/anaconda3/envs/airflow/lib/python3.7/site-packages/airflow/models/dagbag.py", line 339, in parse
    loader.exec_module(new_module)
  File "<frozen importlib._bootstrap_external>", line 728, in exec_module
  File "<frozen importlib._bootstrap>", line 219, in _call_with_frames_removed
  File "/home/kallox/airflow/dags/download_vdjdb.py", line 15, in <module>
    download_files = PythonOperator(task_id='download_files', python_callable=download)
NameError: name 'download' is not defined
[2023-01-01T20:47:09.031-0300] {processor.py:755} WARNING - No viable dags retrieved from /home/kallox/airflow/dags/download_vdjdb.py
[2023-01-01T20:47:09.055-0300] {processor.py:175} INFO - Processing /home/kallox/airflow/dags/download_vdjdb.py took 0.037 seconds
[2023-01-01T20:47:39.398-0300] {processor.py:153} INFO - Started process (PID=9143) to work on /home/kallox/airflow/dags/download_vdjdb.py
[2023-01-01T20:47:39.399-0300] {processor.py:743} INFO - Processing file /home/kallox/airflow/dags/download_vdjdb.py for tasks to queue
[2023-01-01T20:47:39.400-0300] {logging_mixin.py:137} INFO - [2023-01-01T20:47:39.400-0300] {dagbag.py:538} INFO - Filling up the DagBag from /home/kallox/airflow/dags/download_vdjdb.py
[2023-01-01T20:47:39.410-0300] {logging_mixin.py:137} INFO - [2023-01-01T20:47:39.408-0300] {dagbag.py:343} ERROR - Failed to import: /home/kallox/airflow/dags/download_vdjdb.py
Traceback (most recent call last):
  File "/home/kallox/anaconda3/envs/airflow/lib/python3.7/site-packages/airflow/models/dagbag.py", line 339, in parse
    loader.exec_module(new_module)
  File "<frozen importlib._bootstrap_external>", line 728, in exec_module
  File "<frozen importlib._bootstrap>", line 219, in _call_with_frames_removed
  File "/home/kallox/airflow/dags/download_vdjdb.py", line 15, in <module>
    download_files = PythonOperator(task_id='download_files', python_callable=download)
NameError: name 'download' is not defined
[2023-01-01T20:47:39.411-0300] {processor.py:755} WARNING - No viable dags retrieved from /home/kallox/airflow/dags/download_vdjdb.py
[2023-01-01T20:47:39.441-0300] {processor.py:175} INFO - Processing /home/kallox/airflow/dags/download_vdjdb.py took 0.046 seconds
[2023-01-01T20:48:09.613-0300] {processor.py:153} INFO - Started process (PID=9211) to work on /home/kallox/airflow/dags/download_vdjdb.py
[2023-01-01T20:48:09.614-0300] {processor.py:743} INFO - Processing file /home/kallox/airflow/dags/download_vdjdb.py for tasks to queue
[2023-01-01T20:48:09.614-0300] {logging_mixin.py:137} INFO - [2023-01-01T20:48:09.614-0300] {dagbag.py:538} INFO - Filling up the DagBag from /home/kallox/airflow/dags/download_vdjdb.py
[2023-01-01T20:48:09.622-0300] {logging_mixin.py:137} INFO - [2023-01-01T20:48:09.622-0300] {dagbag.py:343} ERROR - Failed to import: /home/kallox/airflow/dags/download_vdjdb.py
Traceback (most recent call last):
  File "/home/kallox/anaconda3/envs/airflow/lib/python3.7/site-packages/airflow/models/dagbag.py", line 339, in parse
    loader.exec_module(new_module)
  File "<frozen importlib._bootstrap_external>", line 728, in exec_module
  File "<frozen importlib._bootstrap>", line 219, in _call_with_frames_removed
  File "/home/kallox/airflow/dags/download_vdjdb.py", line 15, in <module>
    download_files = PythonOperator(task_id='download_files', python_callable=download)
NameError: name 'download' is not defined
[2023-01-01T20:48:09.622-0300] {processor.py:755} WARNING - No viable dags retrieved from /home/kallox/airflow/dags/download_vdjdb.py
[2023-01-01T20:48:09.642-0300] {processor.py:175} INFO - Processing /home/kallox/airflow/dags/download_vdjdb.py took 0.030 seconds
[2023-01-01T20:48:40.212-0300] {processor.py:153} INFO - Started process (PID=9299) to work on /home/kallox/airflow/dags/download_vdjdb.py
[2023-01-01T20:48:40.213-0300] {processor.py:743} INFO - Processing file /home/kallox/airflow/dags/download_vdjdb.py for tasks to queue
[2023-01-01T20:48:40.213-0300] {logging_mixin.py:137} INFO - [2023-01-01T20:48:40.213-0300] {dagbag.py:538} INFO - Filling up the DagBag from /home/kallox/airflow/dags/download_vdjdb.py
[2023-01-01T20:48:40.220-0300] {logging_mixin.py:137} INFO - [2023-01-01T20:48:40.220-0300] {dagbag.py:343} ERROR - Failed to import: /home/kallox/airflow/dags/download_vdjdb.py
Traceback (most recent call last):
  File "/home/kallox/anaconda3/envs/airflow/lib/python3.7/site-packages/airflow/models/dagbag.py", line 339, in parse
    loader.exec_module(new_module)
  File "<frozen importlib._bootstrap_external>", line 728, in exec_module
  File "<frozen importlib._bootstrap>", line 219, in _call_with_frames_removed
  File "/home/kallox/airflow/dags/download_vdjdb.py", line 15, in <module>
    download_files = PythonOperator(task_id='download_files', python_callable=download)
NameError: name 'download' is not defined
[2023-01-01T20:48:40.221-0300] {processor.py:755} WARNING - No viable dags retrieved from /home/kallox/airflow/dags/download_vdjdb.py
[2023-01-01T20:48:40.242-0300] {processor.py:175} INFO - Processing /home/kallox/airflow/dags/download_vdjdb.py took 0.033 seconds
[2023-01-01T20:49:10.605-0300] {processor.py:153} INFO - Started process (PID=9380) to work on /home/kallox/airflow/dags/download_vdjdb.py
[2023-01-01T20:49:10.606-0300] {processor.py:743} INFO - Processing file /home/kallox/airflow/dags/download_vdjdb.py for tasks to queue
[2023-01-01T20:49:10.606-0300] {logging_mixin.py:137} INFO - [2023-01-01T20:49:10.606-0300] {dagbag.py:538} INFO - Filling up the DagBag from /home/kallox/airflow/dags/download_vdjdb.py
[2023-01-01T20:49:10.613-0300] {logging_mixin.py:137} INFO - [2023-01-01T20:49:10.612-0300] {dagbag.py:343} ERROR - Failed to import: /home/kallox/airflow/dags/download_vdjdb.py
Traceback (most recent call last):
  File "/home/kallox/anaconda3/envs/airflow/lib/python3.7/site-packages/airflow/models/dagbag.py", line 339, in parse
    loader.exec_module(new_module)
  File "<frozen importlib._bootstrap_external>", line 728, in exec_module
  File "<frozen importlib._bootstrap>", line 219, in _call_with_frames_removed
  File "/home/kallox/airflow/dags/download_vdjdb.py", line 15, in <module>
    download_files = PythonOperator(task_id='download_files', python_callable=download)
NameError: name 'download' is not defined
[2023-01-01T20:49:10.613-0300] {processor.py:755} WARNING - No viable dags retrieved from /home/kallox/airflow/dags/download_vdjdb.py
[2023-01-01T20:49:10.633-0300] {processor.py:175} INFO - Processing /home/kallox/airflow/dags/download_vdjdb.py took 0.030 seconds
[2023-01-01T20:49:41.575-0300] {processor.py:153} INFO - Started process (PID=9456) to work on /home/kallox/airflow/dags/download_vdjdb.py
[2023-01-01T20:49:41.576-0300] {processor.py:743} INFO - Processing file /home/kallox/airflow/dags/download_vdjdb.py for tasks to queue
[2023-01-01T20:49:41.576-0300] {logging_mixin.py:137} INFO - [2023-01-01T20:49:41.576-0300] {dagbag.py:538} INFO - Filling up the DagBag from /home/kallox/airflow/dags/download_vdjdb.py
[2023-01-01T20:49:41.586-0300] {logging_mixin.py:137} INFO - [2023-01-01T20:49:41.585-0300] {dagbag.py:343} ERROR - Failed to import: /home/kallox/airflow/dags/download_vdjdb.py
Traceback (most recent call last):
  File "/home/kallox/anaconda3/envs/airflow/lib/python3.7/site-packages/airflow/models/dagbag.py", line 339, in parse
    loader.exec_module(new_module)
  File "<frozen importlib._bootstrap_external>", line 728, in exec_module
  File "<frozen importlib._bootstrap>", line 219, in _call_with_frames_removed
  File "/home/kallox/airflow/dags/download_vdjdb.py", line 15, in <module>
    download_files = PythonOperator(task_id='download_files', python_callable=download)
NameError: name 'download' is not defined
[2023-01-01T20:49:41.587-0300] {processor.py:755} WARNING - No viable dags retrieved from /home/kallox/airflow/dags/download_vdjdb.py
[2023-01-01T20:49:41.611-0300] {processor.py:175} INFO - Processing /home/kallox/airflow/dags/download_vdjdb.py took 0.038 seconds
[2023-01-01T20:50:12.334-0300] {processor.py:153} INFO - Started process (PID=9535) to work on /home/kallox/airflow/dags/download_vdjdb.py
[2023-01-01T20:50:12.334-0300] {processor.py:743} INFO - Processing file /home/kallox/airflow/dags/download_vdjdb.py for tasks to queue
[2023-01-01T20:50:12.335-0300] {logging_mixin.py:137} INFO - [2023-01-01T20:50:12.335-0300] {dagbag.py:538} INFO - Filling up the DagBag from /home/kallox/airflow/dags/download_vdjdb.py
[2023-01-01T20:50:12.342-0300] {logging_mixin.py:137} INFO - [2023-01-01T20:50:12.341-0300] {dagbag.py:343} ERROR - Failed to import: /home/kallox/airflow/dags/download_vdjdb.py
Traceback (most recent call last):
  File "/home/kallox/anaconda3/envs/airflow/lib/python3.7/site-packages/airflow/models/dagbag.py", line 339, in parse
    loader.exec_module(new_module)
  File "<frozen importlib._bootstrap_external>", line 728, in exec_module
  File "<frozen importlib._bootstrap>", line 219, in _call_with_frames_removed
  File "/home/kallox/airflow/dags/download_vdjdb.py", line 15, in <module>
    download_files = PythonOperator(task_id='download_files', python_callable=download)
NameError: name 'download' is not defined
[2023-01-01T20:50:12.342-0300] {processor.py:755} WARNING - No viable dags retrieved from /home/kallox/airflow/dags/download_vdjdb.py
[2023-01-01T20:50:12.362-0300] {processor.py:175} INFO - Processing /home/kallox/airflow/dags/download_vdjdb.py took 0.031 seconds
[2023-01-01T20:50:42.959-0300] {processor.py:153} INFO - Started process (PID=9611) to work on /home/kallox/airflow/dags/download_vdjdb.py
[2023-01-01T20:50:42.960-0300] {processor.py:743} INFO - Processing file /home/kallox/airflow/dags/download_vdjdb.py for tasks to queue
[2023-01-01T20:50:42.960-0300] {logging_mixin.py:137} INFO - [2023-01-01T20:50:42.960-0300] {dagbag.py:538} INFO - Filling up the DagBag from /home/kallox/airflow/dags/download_vdjdb.py
[2023-01-01T20:50:42.969-0300] {logging_mixin.py:137} INFO - [2023-01-01T20:50:42.967-0300] {dagbag.py:343} ERROR - Failed to import: /home/kallox/airflow/dags/download_vdjdb.py
Traceback (most recent call last):
  File "/home/kallox/anaconda3/envs/airflow/lib/python3.7/site-packages/airflow/models/dagbag.py", line 339, in parse
    loader.exec_module(new_module)
  File "<frozen importlib._bootstrap_external>", line 728, in exec_module
  File "<frozen importlib._bootstrap>", line 219, in _call_with_frames_removed
  File "/home/kallox/airflow/dags/download_vdjdb.py", line 15, in <module>
    download_files = PythonOperator(task_id='download_files', python_callable=download)
NameError: name 'download' is not defined
[2023-01-01T20:50:42.969-0300] {processor.py:755} WARNING - No viable dags retrieved from /home/kallox/airflow/dags/download_vdjdb.py
[2023-01-01T20:50:42.990-0300] {processor.py:175} INFO - Processing /home/kallox/airflow/dags/download_vdjdb.py took 0.033 seconds
[2023-01-01T20:51:13.345-0300] {processor.py:153} INFO - Started process (PID=9694) to work on /home/kallox/airflow/dags/download_vdjdb.py
[2023-01-01T20:51:13.345-0300] {processor.py:743} INFO - Processing file /home/kallox/airflow/dags/download_vdjdb.py for tasks to queue
[2023-01-01T20:51:13.346-0300] {logging_mixin.py:137} INFO - [2023-01-01T20:51:13.346-0300] {dagbag.py:538} INFO - Filling up the DagBag from /home/kallox/airflow/dags/download_vdjdb.py
[2023-01-01T20:51:13.352-0300] {logging_mixin.py:137} INFO - [2023-01-01T20:51:13.352-0300] {dagbag.py:343} ERROR - Failed to import: /home/kallox/airflow/dags/download_vdjdb.py
Traceback (most recent call last):
  File "/home/kallox/anaconda3/envs/airflow/lib/python3.7/site-packages/airflow/models/dagbag.py", line 339, in parse
    loader.exec_module(new_module)
  File "<frozen importlib._bootstrap_external>", line 728, in exec_module
  File "<frozen importlib._bootstrap>", line 219, in _call_with_frames_removed
  File "/home/kallox/airflow/dags/download_vdjdb.py", line 15, in <module>
    download_files = PythonOperator(task_id='download_files', python_callable=download)
NameError: name 'download' is not defined
[2023-01-01T20:51:13.353-0300] {processor.py:755} WARNING - No viable dags retrieved from /home/kallox/airflow/dags/download_vdjdb.py
[2023-01-01T20:51:13.371-0300] {processor.py:175} INFO - Processing /home/kallox/airflow/dags/download_vdjdb.py took 0.028 seconds
[2023-01-01T20:51:44.267-0300] {processor.py:153} INFO - Started process (PID=9785) to work on /home/kallox/airflow/dags/download_vdjdb.py
[2023-01-01T20:51:44.268-0300] {processor.py:743} INFO - Processing file /home/kallox/airflow/dags/download_vdjdb.py for tasks to queue
[2023-01-01T20:51:44.269-0300] {logging_mixin.py:137} INFO - [2023-01-01T20:51:44.269-0300] {dagbag.py:538} INFO - Filling up the DagBag from /home/kallox/airflow/dags/download_vdjdb.py
[2023-01-01T20:51:44.278-0300] {logging_mixin.py:137} INFO - [2023-01-01T20:51:44.278-0300] {dagbag.py:343} ERROR - Failed to import: /home/kallox/airflow/dags/download_vdjdb.py
Traceback (most recent call last):
  File "/home/kallox/anaconda3/envs/airflow/lib/python3.7/site-packages/airflow/models/dagbag.py", line 339, in parse
    loader.exec_module(new_module)
  File "<frozen importlib._bootstrap_external>", line 728, in exec_module
  File "<frozen importlib._bootstrap>", line 219, in _call_with_frames_removed
  File "/home/kallox/airflow/dags/download_vdjdb.py", line 15, in <module>
    download_files = PythonOperator(task_id='download_files', python_callable=download)
NameError: name 'download' is not defined
[2023-01-01T20:51:44.279-0300] {processor.py:755} WARNING - No viable dags retrieved from /home/kallox/airflow/dags/download_vdjdb.py
[2023-01-01T20:51:44.309-0300] {processor.py:175} INFO - Processing /home/kallox/airflow/dags/download_vdjdb.py took 0.047 seconds
[2023-01-01T20:52:15.204-0300] {processor.py:153} INFO - Started process (PID=9864) to work on /home/kallox/airflow/dags/download_vdjdb.py
[2023-01-01T20:52:15.206-0300] {processor.py:743} INFO - Processing file /home/kallox/airflow/dags/download_vdjdb.py for tasks to queue
[2023-01-01T20:52:15.207-0300] {logging_mixin.py:137} INFO - [2023-01-01T20:52:15.206-0300] {dagbag.py:538} INFO - Filling up the DagBag from /home/kallox/airflow/dags/download_vdjdb.py
[2023-01-01T20:52:15.216-0300] {logging_mixin.py:137} INFO - [2023-01-01T20:52:15.215-0300] {dagbag.py:343} ERROR - Failed to import: /home/kallox/airflow/dags/download_vdjdb.py
Traceback (most recent call last):
  File "/home/kallox/anaconda3/envs/airflow/lib/python3.7/site-packages/airflow/models/dagbag.py", line 339, in parse
    loader.exec_module(new_module)
  File "<frozen importlib._bootstrap_external>", line 728, in exec_module
  File "<frozen importlib._bootstrap>", line 219, in _call_with_frames_removed
  File "/home/kallox/airflow/dags/download_vdjdb.py", line 15, in <module>
    download_files = PythonOperator(task_id='download_files', python_callable=download)
NameError: name 'download' is not defined
[2023-01-01T20:52:15.216-0300] {processor.py:755} WARNING - No viable dags retrieved from /home/kallox/airflow/dags/download_vdjdb.py
[2023-01-01T20:52:15.252-0300] {processor.py:175} INFO - Processing /home/kallox/airflow/dags/download_vdjdb.py took 0.051 seconds
[2023-01-01T20:52:45.680-0300] {processor.py:153} INFO - Started process (PID=10071) to work on /home/kallox/airflow/dags/download_vdjdb.py
[2023-01-01T20:52:45.681-0300] {processor.py:743} INFO - Processing file /home/kallox/airflow/dags/download_vdjdb.py for tasks to queue
[2023-01-01T20:52:45.681-0300] {logging_mixin.py:137} INFO - [2023-01-01T20:52:45.681-0300] {dagbag.py:538} INFO - Filling up the DagBag from /home/kallox/airflow/dags/download_vdjdb.py
[2023-01-01T20:52:45.687-0300] {logging_mixin.py:137} INFO - [2023-01-01T20:52:45.687-0300] {dagbag.py:343} ERROR - Failed to import: /home/kallox/airflow/dags/download_vdjdb.py
Traceback (most recent call last):
  File "/home/kallox/anaconda3/envs/airflow/lib/python3.7/site-packages/airflow/models/dagbag.py", line 339, in parse
    loader.exec_module(new_module)
  File "<frozen importlib._bootstrap_external>", line 728, in exec_module
  File "<frozen importlib._bootstrap>", line 219, in _call_with_frames_removed
  File "/home/kallox/airflow/dags/download_vdjdb.py", line 15, in <module>
    download_files = PythonOperator(task_id='download_files', python_callable=download)
NameError: name 'download' is not defined
[2023-01-01T20:52:45.688-0300] {processor.py:755} WARNING - No viable dags retrieved from /home/kallox/airflow/dags/download_vdjdb.py
[2023-01-01T20:52:45.706-0300] {processor.py:175} INFO - Processing /home/kallox/airflow/dags/download_vdjdb.py took 0.027 seconds
[2023-01-01T20:53:16.325-0300] {processor.py:153} INFO - Started process (PID=10219) to work on /home/kallox/airflow/dags/download_vdjdb.py
[2023-01-01T20:53:16.326-0300] {processor.py:743} INFO - Processing file /home/kallox/airflow/dags/download_vdjdb.py for tasks to queue
[2023-01-01T20:53:16.326-0300] {logging_mixin.py:137} INFO - [2023-01-01T20:53:16.326-0300] {dagbag.py:538} INFO - Filling up the DagBag from /home/kallox/airflow/dags/download_vdjdb.py
[2023-01-01T20:53:16.332-0300] {logging_mixin.py:137} INFO - [2023-01-01T20:53:16.332-0300] {dagbag.py:343} ERROR - Failed to import: /home/kallox/airflow/dags/download_vdjdb.py
Traceback (most recent call last):
  File "/home/kallox/anaconda3/envs/airflow/lib/python3.7/site-packages/airflow/models/dagbag.py", line 339, in parse
    loader.exec_module(new_module)
  File "<frozen importlib._bootstrap_external>", line 728, in exec_module
  File "<frozen importlib._bootstrap>", line 219, in _call_with_frames_removed
  File "/home/kallox/airflow/dags/download_vdjdb.py", line 15, in <module>
    download_files = PythonOperator(task_id='download_files', python_callable=download)
NameError: name 'download' is not defined
[2023-01-01T20:53:16.333-0300] {processor.py:755} WARNING - No viable dags retrieved from /home/kallox/airflow/dags/download_vdjdb.py
[2023-01-01T20:53:16.352-0300] {processor.py:175} INFO - Processing /home/kallox/airflow/dags/download_vdjdb.py took 0.029 seconds
[2023-01-01T20:53:47.097-0300] {processor.py:153} INFO - Started process (PID=10385) to work on /home/kallox/airflow/dags/download_vdjdb.py
[2023-01-01T20:53:47.098-0300] {processor.py:743} INFO - Processing file /home/kallox/airflow/dags/download_vdjdb.py for tasks to queue
[2023-01-01T20:53:47.099-0300] {logging_mixin.py:137} INFO - [2023-01-01T20:53:47.098-0300] {dagbag.py:538} INFO - Filling up the DagBag from /home/kallox/airflow/dags/download_vdjdb.py
[2023-01-01T20:53:47.105-0300] {logging_mixin.py:137} INFO - [2023-01-01T20:53:47.104-0300] {dagbag.py:343} ERROR - Failed to import: /home/kallox/airflow/dags/download_vdjdb.py
Traceback (most recent call last):
  File "/home/kallox/anaconda3/envs/airflow/lib/python3.7/site-packages/airflow/models/dagbag.py", line 339, in parse
    loader.exec_module(new_module)
  File "<frozen importlib._bootstrap_external>", line 728, in exec_module
  File "<frozen importlib._bootstrap>", line 219, in _call_with_frames_removed
  File "/home/kallox/airflow/dags/download_vdjdb.py", line 15, in <module>
    download_files = PythonOperator(task_id='download_files', python_callable=download)
NameError: name 'download' is not defined
[2023-01-01T20:53:47.105-0300] {processor.py:755} WARNING - No viable dags retrieved from /home/kallox/airflow/dags/download_vdjdb.py
[2023-01-01T20:53:47.125-0300] {processor.py:175} INFO - Processing /home/kallox/airflow/dags/download_vdjdb.py took 0.029 seconds
[2023-01-01T20:54:17.635-0300] {processor.py:153} INFO - Started process (PID=10516) to work on /home/kallox/airflow/dags/download_vdjdb.py
[2023-01-01T20:54:17.635-0300] {processor.py:743} INFO - Processing file /home/kallox/airflow/dags/download_vdjdb.py for tasks to queue
[2023-01-01T20:54:17.636-0300] {logging_mixin.py:137} INFO - [2023-01-01T20:54:17.636-0300] {dagbag.py:538} INFO - Filling up the DagBag from /home/kallox/airflow/dags/download_vdjdb.py
[2023-01-01T20:54:17.642-0300] {logging_mixin.py:137} INFO - [2023-01-01T20:54:17.641-0300] {dagbag.py:343} ERROR - Failed to import: /home/kallox/airflow/dags/download_vdjdb.py
Traceback (most recent call last):
  File "/home/kallox/anaconda3/envs/airflow/lib/python3.7/site-packages/airflow/models/dagbag.py", line 339, in parse
    loader.exec_module(new_module)
  File "<frozen importlib._bootstrap_external>", line 728, in exec_module
  File "<frozen importlib._bootstrap>", line 219, in _call_with_frames_removed
  File "/home/kallox/airflow/dags/download_vdjdb.py", line 15, in <module>
    download_files = PythonOperator(task_id='download_files', python_callable=download)
NameError: name 'download' is not defined
[2023-01-01T20:54:17.642-0300] {processor.py:755} WARNING - No viable dags retrieved from /home/kallox/airflow/dags/download_vdjdb.py
[2023-01-01T20:54:17.661-0300] {processor.py:175} INFO - Processing /home/kallox/airflow/dags/download_vdjdb.py took 0.028 seconds
[2023-01-01T20:54:50.518-0300] {processor.py:153} INFO - Started process (PID=10644) to work on /home/kallox/airflow/dags/download_vdjdb.py
[2023-01-01T20:54:50.519-0300] {processor.py:743} INFO - Processing file /home/kallox/airflow/dags/download_vdjdb.py for tasks to queue
[2023-01-01T20:54:50.519-0300] {logging_mixin.py:137} INFO - [2023-01-01T20:54:50.519-0300] {dagbag.py:538} INFO - Filling up the DagBag from /home/kallox/airflow/dags/download_vdjdb.py
[2023-01-01T20:54:50.527-0300] {logging_mixin.py:137} INFO - [2023-01-01T20:54:50.526-0300] {dagbag.py:343} ERROR - Failed to import: /home/kallox/airflow/dags/download_vdjdb.py
Traceback (most recent call last):
  File "/home/kallox/anaconda3/envs/airflow/lib/python3.7/site-packages/airflow/models/dagbag.py", line 339, in parse
    loader.exec_module(new_module)
  File "<frozen importlib._bootstrap_external>", line 728, in exec_module
  File "<frozen importlib._bootstrap>", line 219, in _call_with_frames_removed
  File "/home/kallox/airflow/dags/download_vdjdb.py", line 15, in <module>
    download_files = PythonOperator(task_id='download_files', python_callable=download)
NameError: name 'download' is not defined
[2023-01-01T20:54:50.527-0300] {processor.py:755} WARNING - No viable dags retrieved from /home/kallox/airflow/dags/download_vdjdb.py
[2023-01-01T20:54:50.546-0300] {processor.py:175} INFO - Processing /home/kallox/airflow/dags/download_vdjdb.py took 0.031 seconds
[2023-01-01T20:55:22.118-0300] {processor.py:153} INFO - Started process (PID=10768) to work on /home/kallox/airflow/dags/download_vdjdb.py
[2023-01-01T20:55:22.119-0300] {processor.py:743} INFO - Processing file /home/kallox/airflow/dags/download_vdjdb.py for tasks to queue
[2023-01-01T20:55:22.120-0300] {logging_mixin.py:137} INFO - [2023-01-01T20:55:22.120-0300] {dagbag.py:538} INFO - Filling up the DagBag from /home/kallox/airflow/dags/download_vdjdb.py
[2023-01-01T20:55:22.128-0300] {logging_mixin.py:137} INFO - [2023-01-01T20:55:22.127-0300] {dagbag.py:343} ERROR - Failed to import: /home/kallox/airflow/dags/download_vdjdb.py
Traceback (most recent call last):
  File "/home/kallox/anaconda3/envs/airflow/lib/python3.7/site-packages/airflow/models/dagbag.py", line 339, in parse
    loader.exec_module(new_module)
  File "<frozen importlib._bootstrap_external>", line 728, in exec_module
  File "<frozen importlib._bootstrap>", line 219, in _call_with_frames_removed
  File "/home/kallox/airflow/dags/download_vdjdb.py", line 15, in <module>
    download_files = PythonOperator(task_id='download_files', python_callable=download)
NameError: name 'download' is not defined
[2023-01-01T20:55:22.129-0300] {processor.py:755} WARNING - No viable dags retrieved from /home/kallox/airflow/dags/download_vdjdb.py
[2023-01-01T20:55:22.151-0300] {processor.py:175} INFO - Processing /home/kallox/airflow/dags/download_vdjdb.py took 0.035 seconds
[2023-01-01T20:55:52.396-0300] {processor.py:153} INFO - Started process (PID=10883) to work on /home/kallox/airflow/dags/download_vdjdb.py
[2023-01-01T20:55:52.397-0300] {processor.py:743} INFO - Processing file /home/kallox/airflow/dags/download_vdjdb.py for tasks to queue
[2023-01-01T20:55:52.397-0300] {logging_mixin.py:137} INFO - [2023-01-01T20:55:52.397-0300] {dagbag.py:538} INFO - Filling up the DagBag from /home/kallox/airflow/dags/download_vdjdb.py
[2023-01-01T20:55:52.403-0300] {logging_mixin.py:137} INFO - [2023-01-01T20:55:52.403-0300] {dagbag.py:343} ERROR - Failed to import: /home/kallox/airflow/dags/download_vdjdb.py
Traceback (most recent call last):
  File "/home/kallox/anaconda3/envs/airflow/lib/python3.7/site-packages/airflow/models/dagbag.py", line 339, in parse
    loader.exec_module(new_module)
  File "<frozen importlib._bootstrap_external>", line 728, in exec_module
  File "<frozen importlib._bootstrap>", line 219, in _call_with_frames_removed
  File "/home/kallox/airflow/dags/download_vdjdb.py", line 15, in <module>
    download_files = PythonOperator(task_id='download_files', python_callable=download)
NameError: name 'download' is not defined
[2023-01-01T20:55:52.404-0300] {processor.py:755} WARNING - No viable dags retrieved from /home/kallox/airflow/dags/download_vdjdb.py
[2023-01-01T20:55:52.423-0300] {processor.py:175} INFO - Processing /home/kallox/airflow/dags/download_vdjdb.py took 0.030 seconds
[2023-01-01T20:56:24.273-0300] {processor.py:153} INFO - Started process (PID=10971) to work on /home/kallox/airflow/dags/download_vdjdb.py
[2023-01-01T20:56:24.274-0300] {processor.py:743} INFO - Processing file /home/kallox/airflow/dags/download_vdjdb.py for tasks to queue
[2023-01-01T20:56:24.275-0300] {logging_mixin.py:137} INFO - [2023-01-01T20:56:24.274-0300] {dagbag.py:538} INFO - Filling up the DagBag from /home/kallox/airflow/dags/download_vdjdb.py
[2023-01-01T20:56:24.284-0300] {logging_mixin.py:137} INFO - [2023-01-01T20:56:24.284-0300] {dagbag.py:343} ERROR - Failed to import: /home/kallox/airflow/dags/download_vdjdb.py
Traceback (most recent call last):
  File "/home/kallox/anaconda3/envs/airflow/lib/python3.7/site-packages/airflow/models/dagbag.py", line 339, in parse
    loader.exec_module(new_module)
  File "<frozen importlib._bootstrap_external>", line 728, in exec_module
  File "<frozen importlib._bootstrap>", line 219, in _call_with_frames_removed
  File "/home/kallox/airflow/dags/download_vdjdb.py", line 15, in <module>
    download_files = PythonOperator(task_id='download_files', python_callable=download)
NameError: name 'download' is not defined
[2023-01-01T20:56:24.285-0300] {processor.py:755} WARNING - No viable dags retrieved from /home/kallox/airflow/dags/download_vdjdb.py
[2023-01-01T20:56:24.315-0300] {processor.py:175} INFO - Processing /home/kallox/airflow/dags/download_vdjdb.py took 0.045 seconds
[2023-01-01T20:56:54.970-0300] {processor.py:153} INFO - Started process (PID=11048) to work on /home/kallox/airflow/dags/download_vdjdb.py
[2023-01-01T20:56:54.971-0300] {processor.py:743} INFO - Processing file /home/kallox/airflow/dags/download_vdjdb.py for tasks to queue
[2023-01-01T20:56:54.971-0300] {logging_mixin.py:137} INFO - [2023-01-01T20:56:54.971-0300] {dagbag.py:538} INFO - Filling up the DagBag from /home/kallox/airflow/dags/download_vdjdb.py
[2023-01-01T20:56:54.979-0300] {logging_mixin.py:137} INFO - [2023-01-01T20:56:54.978-0300] {dagbag.py:343} ERROR - Failed to import: /home/kallox/airflow/dags/download_vdjdb.py
Traceback (most recent call last):
  File "/home/kallox/anaconda3/envs/airflow/lib/python3.7/site-packages/airflow/models/dagbag.py", line 339, in parse
    loader.exec_module(new_module)
  File "<frozen importlib._bootstrap_external>", line 728, in exec_module
  File "<frozen importlib._bootstrap>", line 219, in _call_with_frames_removed
  File "/home/kallox/airflow/dags/download_vdjdb.py", line 15, in <module>
    download_files = PythonOperator(task_id='download_files', python_callable=download)
NameError: name 'download' is not defined
[2023-01-01T20:56:54.979-0300] {processor.py:755} WARNING - No viable dags retrieved from /home/kallox/airflow/dags/download_vdjdb.py
[2023-01-01T20:56:54.999-0300] {processor.py:175} INFO - Processing /home/kallox/airflow/dags/download_vdjdb.py took 0.032 seconds
[2023-01-01T20:57:25.575-0300] {processor.py:153} INFO - Started process (PID=11123) to work on /home/kallox/airflow/dags/download_vdjdb.py
[2023-01-01T20:57:25.576-0300] {processor.py:743} INFO - Processing file /home/kallox/airflow/dags/download_vdjdb.py for tasks to queue
[2023-01-01T20:57:25.576-0300] {logging_mixin.py:137} INFO - [2023-01-01T20:57:25.576-0300] {dagbag.py:538} INFO - Filling up the DagBag from /home/kallox/airflow/dags/download_vdjdb.py
[2023-01-01T20:57:25.582-0300] {logging_mixin.py:137} INFO - [2023-01-01T20:57:25.581-0300] {dagbag.py:343} ERROR - Failed to import: /home/kallox/airflow/dags/download_vdjdb.py
Traceback (most recent call last):
  File "/home/kallox/anaconda3/envs/airflow/lib/python3.7/site-packages/airflow/models/dagbag.py", line 339, in parse
    loader.exec_module(new_module)
  File "<frozen importlib._bootstrap_external>", line 728, in exec_module
  File "<frozen importlib._bootstrap>", line 219, in _call_with_frames_removed
  File "/home/kallox/airflow/dags/download_vdjdb.py", line 15, in <module>
    download_files = PythonOperator(task_id='download_files', python_callable=download)
NameError: name 'download' is not defined
[2023-01-01T20:57:25.582-0300] {processor.py:755} WARNING - No viable dags retrieved from /home/kallox/airflow/dags/download_vdjdb.py
[2023-01-01T20:57:25.601-0300] {processor.py:175} INFO - Processing /home/kallox/airflow/dags/download_vdjdb.py took 0.027 seconds
[2023-01-01T20:57:56.145-0300] {processor.py:153} INFO - Started process (PID=11197) to work on /home/kallox/airflow/dags/download_vdjdb.py
[2023-01-01T20:57:56.146-0300] {processor.py:743} INFO - Processing file /home/kallox/airflow/dags/download_vdjdb.py for tasks to queue
[2023-01-01T20:57:56.146-0300] {logging_mixin.py:137} INFO - [2023-01-01T20:57:56.146-0300] {dagbag.py:538} INFO - Filling up the DagBag from /home/kallox/airflow/dags/download_vdjdb.py
[2023-01-01T20:57:56.154-0300] {logging_mixin.py:137} INFO - [2023-01-01T20:57:56.154-0300] {dagbag.py:343} ERROR - Failed to import: /home/kallox/airflow/dags/download_vdjdb.py
Traceback (most recent call last):
  File "/home/kallox/anaconda3/envs/airflow/lib/python3.7/site-packages/airflow/models/dagbag.py", line 339, in parse
    loader.exec_module(new_module)
  File "<frozen importlib._bootstrap_external>", line 728, in exec_module
  File "<frozen importlib._bootstrap>", line 219, in _call_with_frames_removed
  File "/home/kallox/airflow/dags/download_vdjdb.py", line 15, in <module>
    download_files = PythonOperator(task_id='download_files', python_callable=download)
NameError: name 'download' is not defined
[2023-01-01T20:57:56.155-0300] {processor.py:755} WARNING - No viable dags retrieved from /home/kallox/airflow/dags/download_vdjdb.py
[2023-01-01T20:57:56.174-0300] {processor.py:175} INFO - Processing /home/kallox/airflow/dags/download_vdjdb.py took 0.031 seconds
[2023-01-01T20:58:26.740-0300] {processor.py:153} INFO - Started process (PID=11272) to work on /home/kallox/airflow/dags/download_vdjdb.py
[2023-01-01T20:58:26.741-0300] {processor.py:743} INFO - Processing file /home/kallox/airflow/dags/download_vdjdb.py for tasks to queue
[2023-01-01T20:58:26.742-0300] {logging_mixin.py:137} INFO - [2023-01-01T20:58:26.742-0300] {dagbag.py:538} INFO - Filling up the DagBag from /home/kallox/airflow/dags/download_vdjdb.py
[2023-01-01T20:58:26.749-0300] {logging_mixin.py:137} INFO - [2023-01-01T20:58:26.748-0300] {dagbag.py:343} ERROR - Failed to import: /home/kallox/airflow/dags/download_vdjdb.py
Traceback (most recent call last):
  File "/home/kallox/anaconda3/envs/airflow/lib/python3.7/site-packages/airflow/models/dagbag.py", line 339, in parse
    loader.exec_module(new_module)
  File "<frozen importlib._bootstrap_external>", line 728, in exec_module
  File "<frozen importlib._bootstrap>", line 219, in _call_with_frames_removed
  File "/home/kallox/airflow/dags/download_vdjdb.py", line 15, in <module>
    download_files = PythonOperator(task_id='download_files', python_callable=download)
NameError: name 'download' is not defined
[2023-01-01T20:58:26.749-0300] {processor.py:755} WARNING - No viable dags retrieved from /home/kallox/airflow/dags/download_vdjdb.py
[2023-01-01T20:58:26.767-0300] {processor.py:175} INFO - Processing /home/kallox/airflow/dags/download_vdjdb.py took 0.029 seconds
[2023-01-01T20:58:57.464-0300] {processor.py:153} INFO - Started process (PID=11348) to work on /home/kallox/airflow/dags/download_vdjdb.py
[2023-01-01T20:58:57.464-0300] {processor.py:743} INFO - Processing file /home/kallox/airflow/dags/download_vdjdb.py for tasks to queue
[2023-01-01T20:58:57.465-0300] {logging_mixin.py:137} INFO - [2023-01-01T20:58:57.465-0300] {dagbag.py:538} INFO - Filling up the DagBag from /home/kallox/airflow/dags/download_vdjdb.py
[2023-01-01T20:58:57.472-0300] {logging_mixin.py:137} INFO - [2023-01-01T20:58:57.471-0300] {dagbag.py:343} ERROR - Failed to import: /home/kallox/airflow/dags/download_vdjdb.py
Traceback (most recent call last):
  File "/home/kallox/anaconda3/envs/airflow/lib/python3.7/site-packages/airflow/models/dagbag.py", line 339, in parse
    loader.exec_module(new_module)
  File "<frozen importlib._bootstrap_external>", line 728, in exec_module
  File "<frozen importlib._bootstrap>", line 219, in _call_with_frames_removed
  File "/home/kallox/airflow/dags/download_vdjdb.py", line 15, in <module>
    download_files = PythonOperator(task_id='download_files', python_callable=download)
NameError: name 'download' is not defined
[2023-01-01T20:58:57.472-0300] {processor.py:755} WARNING - No viable dags retrieved from /home/kallox/airflow/dags/download_vdjdb.py
[2023-01-01T20:58:57.492-0300] {processor.py:175} INFO - Processing /home/kallox/airflow/dags/download_vdjdb.py took 0.031 seconds
[2023-01-01T20:59:28.087-0300] {processor.py:153} INFO - Started process (PID=11427) to work on /home/kallox/airflow/dags/download_vdjdb.py
[2023-01-01T20:59:28.087-0300] {processor.py:743} INFO - Processing file /home/kallox/airflow/dags/download_vdjdb.py for tasks to queue
[2023-01-01T20:59:28.088-0300] {logging_mixin.py:137} INFO - [2023-01-01T20:59:28.088-0300] {dagbag.py:538} INFO - Filling up the DagBag from /home/kallox/airflow/dags/download_vdjdb.py
[2023-01-01T20:59:28.095-0300] {logging_mixin.py:137} INFO - [2023-01-01T20:59:28.094-0300] {dagbag.py:343} ERROR - Failed to import: /home/kallox/airflow/dags/download_vdjdb.py
Traceback (most recent call last):
  File "/home/kallox/anaconda3/envs/airflow/lib/python3.7/site-packages/airflow/models/dagbag.py", line 339, in parse
    loader.exec_module(new_module)
  File "<frozen importlib._bootstrap_external>", line 728, in exec_module
  File "<frozen importlib._bootstrap>", line 219, in _call_with_frames_removed
  File "/home/kallox/airflow/dags/download_vdjdb.py", line 15, in <module>
    download_files = PythonOperator(task_id='download_files', python_callable=download)
NameError: name 'download' is not defined
[2023-01-01T20:59:28.095-0300] {processor.py:755} WARNING - No viable dags retrieved from /home/kallox/airflow/dags/download_vdjdb.py
[2023-01-01T20:59:28.113-0300] {processor.py:175} INFO - Processing /home/kallox/airflow/dags/download_vdjdb.py took 0.028 seconds
[2023-01-01T20:59:59.134-0300] {processor.py:153} INFO - Started process (PID=11516) to work on /home/kallox/airflow/dags/download_vdjdb.py
[2023-01-01T20:59:59.135-0300] {processor.py:743} INFO - Processing file /home/kallox/airflow/dags/download_vdjdb.py for tasks to queue
[2023-01-01T20:59:59.135-0300] {logging_mixin.py:137} INFO - [2023-01-01T20:59:59.135-0300] {dagbag.py:538} INFO - Filling up the DagBag from /home/kallox/airflow/dags/download_vdjdb.py
[2023-01-01T20:59:59.142-0300] {logging_mixin.py:137} INFO - [2023-01-01T20:59:59.141-0300] {dagbag.py:343} ERROR - Failed to import: /home/kallox/airflow/dags/download_vdjdb.py
Traceback (most recent call last):
  File "/home/kallox/anaconda3/envs/airflow/lib/python3.7/site-packages/airflow/models/dagbag.py", line 339, in parse
    loader.exec_module(new_module)
  File "<frozen importlib._bootstrap_external>", line 728, in exec_module
  File "<frozen importlib._bootstrap>", line 219, in _call_with_frames_removed
  File "/home/kallox/airflow/dags/download_vdjdb.py", line 15, in <module>
    download_files = PythonOperator(task_id='download_files', python_callable=download)
NameError: name 'download' is not defined
[2023-01-01T20:59:59.142-0300] {processor.py:755} WARNING - No viable dags retrieved from /home/kallox/airflow/dags/download_vdjdb.py
[2023-01-01T20:59:59.163-0300] {processor.py:175} INFO - Processing /home/kallox/airflow/dags/download_vdjdb.py took 0.032 seconds
