[2023-01-03T22:34:32.497-0300] {taskinstance.py:1087} INFO - Dependencies all met for <TaskInstance: get_epitopes.iedb manual__2023-01-04T01:34:28.365599+00:00 [queued]>
[2023-01-03T22:34:32.514-0300] {taskinstance.py:1087} INFO - Dependencies all met for <TaskInstance: get_epitopes.iedb manual__2023-01-04T01:34:28.365599+00:00 [queued]>
[2023-01-03T22:34:32.514-0300] {taskinstance.py:1283} INFO - 
--------------------------------------------------------------------------------
[2023-01-03T22:34:32.515-0300] {taskinstance.py:1284} INFO - Starting attempt 1 of 1
[2023-01-03T22:34:32.515-0300] {taskinstance.py:1285} INFO - 
--------------------------------------------------------------------------------
[2023-01-03T22:34:32.542-0300] {taskinstance.py:1304} INFO - Executing <Task(PythonOperator): iedb> on 2023-01-04 01:34:28.365599+00:00
[2023-01-03T22:34:32.550-0300] {standard_task_runner.py:55} INFO - Started process 21897 to run task
[2023-01-03T22:34:32.553-0300] {standard_task_runner.py:82} INFO - Running: ['***', 'tasks', 'run', 'get_epitopes', 'iedb', 'manual__2023-01-04T01:34:28.365599+00:00', '--job-id', '231', '--raw', '--subdir', 'DAGS_FOLDER/get_epitopes.py', '--cfg-path', '/tmp/tmp1f7ey5dx']
[2023-01-03T22:34:32.554-0300] {standard_task_runner.py:83} INFO - Job 231: Subtask iedb
[2023-01-03T22:34:32.629-0300] {task_command.py:389} INFO - Running <TaskInstance: get_epitopes.iedb manual__2023-01-04T01:34:28.365599+00:00 [running]> on host kallo-Ubuntu
[2023-01-03T22:34:32.714-0300] {taskinstance.py:1513} INFO - Exporting the following env vars:
AIRFLOW_CTX_DAG_OWNER=Kallox
AIRFLOW_CTX_DAG_ID=get_epitopes
AIRFLOW_CTX_TASK_ID=iedb
AIRFLOW_CTX_EXECUTION_DATE=2023-01-04T01:34:28.365599+00:00
AIRFLOW_CTX_TRY_NUMBER=1
AIRFLOW_CTX_DAG_RUN_ID=manual__2023-01-04T01:34:28.365599+00:00
[2023-01-03T22:34:45.442-0300] {logging_mixin.py:137} WARNING - /home/kallox/anaconda3/envs/***/lib/python3.7/site-packages/***/operators/python.py:192 DtypeWarning: Columns (3,4,7,8,17,18,19,20,23,24,25,26,27,28,29,30,31,32) have mixed types.Specify dtype option on import or set low_memory=False.
[2023-01-03T22:34:45.945-0300] {taskinstance.py:1772} ERROR - Task failed with exception
Traceback (most recent call last):
  File "/home/kallox/anaconda3/envs/airflow/lib/python3.7/site-packages/airflow/operators/python.py", line 175, in execute
    return_value = self.execute_callable()
  File "/home/kallox/anaconda3/envs/airflow/lib/python3.7/site-packages/airflow/operators/python.py", line 192, in execute_callable
    return self.python_callable(*self.op_args, **self.op_kwargs)
  File "/home/kallox/airflow/dags/scripts/iedb/drop_columns.py", line 31, in drop_columns_epitopes
    epitope = epitope.drop(columns=columns_to_drop)
  File "/home/kallox/anaconda3/envs/airflow/lib/python3.7/site-packages/pandas/util/_decorators.py", line 311, in wrapper
    return func(*args, **kwargs)
  File "/home/kallox/anaconda3/envs/airflow/lib/python3.7/site-packages/pandas/core/frame.py", line 4913, in drop
    errors=errors,
  File "/home/kallox/anaconda3/envs/airflow/lib/python3.7/site-packages/pandas/core/generic.py", line 4150, in drop
    obj = obj._drop_axis(labels, axis, level=level, errors=errors)
  File "/home/kallox/anaconda3/envs/airflow/lib/python3.7/site-packages/pandas/core/generic.py", line 4185, in _drop_axis
    new_axis = axis.drop(labels, errors=errors)
  File "/home/kallox/anaconda3/envs/airflow/lib/python3.7/site-packages/pandas/core/indexes/base.py", line 6017, in drop
    raise KeyError(f"{labels[mask]} not found in axis")
KeyError: "['Epitope Modified Residue(s)' 'Epitope Modification(s)'\n 'Non-peptidic epitope IRI' 'Parent Protein' 'Parent Protein IRI'\n 'Organism Name' 'Organism IRI' 'Parent Organism' 'Parent Organism IRI'\n 'Epitope Comments' 'Non-peptidic object IRI' 'Parent Protein.1'\n 'Parent Protein IRI.1' 'Organism Name.1' 'Organism IRI.1'\n 'Parent Organism.1' 'Parent Organism IRI.1' 'Epitope Synonyms'\n 'Epitope Relationship' 'Synonyms' 'Antigen IRI.1' 'Antigen Name.1'\n 'Ending Position.1' 'Starting Position.1' 'Description.1' 'Object Type.1'\n 'Starting Position' 'Ending Position' 'Antigen Name'] not found in axis"
[2023-01-03T22:34:45.960-0300] {taskinstance.py:1327} INFO - Marking task as FAILED. dag_id=get_epitopes, task_id=iedb, execution_date=20230104T013428, start_date=20230104T013432, end_date=20230104T013445
[2023-01-03T22:34:45.978-0300] {standard_task_runner.py:105} ERROR - Failed to execute job 231 for task iedb ("['Epitope Modified Residue(s)' 'Epitope Modification(s)'\n 'Non-peptidic epitope IRI' 'Parent Protein' 'Parent Protein IRI'\n 'Organism Name' 'Organism IRI' 'Parent Organism' 'Parent Organism IRI'\n 'Epitope Comments' 'Non-peptidic object IRI' 'Parent Protein.1'\n 'Parent Protein IRI.1' 'Organism Name.1' 'Organism IRI.1'\n 'Parent Organism.1' 'Parent Organism IRI.1' 'Epitope Synonyms'\n 'Epitope Relationship' 'Synonyms' 'Antigen IRI.1' 'Antigen Name.1'\n 'Ending Position.1' 'Starting Position.1' 'Description.1' 'Object Type.1'\n 'Starting Position' 'Ending Position' 'Antigen Name'] not found in axis"; 21897)
[2023-01-03T22:34:46.052-0300] {local_task_job.py:159} INFO - Task exited with return code 1
[2023-01-03T22:34:46.077-0300] {taskinstance.py:2582} INFO - 0 downstream tasks scheduled from follow-on schedule check
