[2022-12-20T22:42:48.536-0300] {taskinstance.py:1087} INFO - Dependencies all met for <TaskInstance: download_iedb.download_files manual__2022-12-21T01:42:46.482640+00:00 [queued]>
[2022-12-20T22:42:48.552-0300] {taskinstance.py:1087} INFO - Dependencies all met for <TaskInstance: download_iedb.download_files manual__2022-12-21T01:42:46.482640+00:00 [queued]>
[2022-12-20T22:42:48.552-0300] {taskinstance.py:1283} INFO - 
--------------------------------------------------------------------------------
[2022-12-20T22:42:48.552-0300] {taskinstance.py:1284} INFO - Starting attempt 1 of 1
[2022-12-20T22:42:48.552-0300] {taskinstance.py:1285} INFO - 
--------------------------------------------------------------------------------
[2022-12-20T22:42:48.572-0300] {taskinstance.py:1304} INFO - Executing <Task(PythonOperator): download_files> on 2022-12-21 01:42:46.482640+00:00
[2022-12-20T22:42:48.577-0300] {standard_task_runner.py:55} INFO - Started process 41476 to run task
[2022-12-20T22:42:48.581-0300] {standard_task_runner.py:82} INFO - Running: ['***', 'tasks', 'run', 'download_iedb', 'download_files', 'manual__2022-12-21T01:42:46.482640+00:00', '--job-id', '24', '--raw', '--subdir', 'DAGS_FOLDER/download_iedb.py', '--cfg-path', '/tmp/tmprc0d6exg']
[2022-12-20T22:42:48.582-0300] {standard_task_runner.py:83} INFO - Job 24: Subtask download_files
[2022-12-20T22:42:48.672-0300] {task_command.py:389} INFO - Running <TaskInstance: download_iedb.download_files manual__2022-12-21T01:42:46.482640+00:00 [running]> on host kallo-Ubuntu
[2022-12-20T22:42:48.768-0300] {taskinstance.py:1513} INFO - Exporting the following env vars:
AIRFLOW_CTX_DAG_OWNER=Kallox
AIRFLOW_CTX_DAG_ID=download_iedb
AIRFLOW_CTX_TASK_ID=download_files
AIRFLOW_CTX_EXECUTION_DATE=2022-12-21T01:42:46.482640+00:00
AIRFLOW_CTX_TRY_NUMBER=1
AIRFLOW_CTX_DAG_RUN_ID=manual__2022-12-21T01:42:46.482640+00:00
[2022-12-20T22:42:51.366-0300] {logging_mixin.py:137} INFO - antigen downloaded.
[2022-12-20T22:42:51.368-0300] {taskinstance.py:1772} ERROR - Task failed with exception
Traceback (most recent call last):
  File "/home/kallox/anaconda3/envs/airflow/lib/python3.7/site-packages/airflow/operators/python.py", line 175, in execute
    return_value = self.execute_callable()
  File "/home/kallox/anaconda3/envs/airflow/lib/python3.7/site-packages/airflow/operators/python.py", line 192, in execute_callable
    return self.python_callable(*self.op_args, **self.op_kwargs)
  File "/home/kallox/airflow/dags/scripts/iedb/download.py", line 32, in download
    get_file(file['link'], file['filename'], file['extension'])
  File "/home/kallox/airflow/dags/scripts/iedb/download.py", line 10, in get_file
    save_file(name, response.content, extension)
  File "/home/kallox/airflow/dags/scripts/iedb/download.py", line 17, in save_file
    file = open('./files/iedb/downloads/'+name+'.'+extension, 'wb')
FileNotFoundError: [Errno 2] No such file or directory: './files/iedb/downloads/antigen.zip'
[2022-12-20T22:42:51.386-0300] {taskinstance.py:1327} INFO - Marking task as FAILED. dag_id=download_iedb, task_id=download_files, execution_date=20221221T014246, start_date=20221221T014248, end_date=20221221T014251
[2022-12-20T22:42:51.410-0300] {standard_task_runner.py:105} ERROR - Failed to execute job 24 for task download_files ([Errno 2] No such file or directory: './files/iedb/downloads/antigen.zip'; 41476)
[2022-12-20T22:42:51.439-0300] {local_task_job.py:159} INFO - Task exited with return code 1
[2022-12-20T22:42:51.487-0300] {taskinstance.py:2582} INFO - 0 downstream tasks scheduled from follow-on schedule check
