[2022-12-14T18:03:42.169-0300] {taskinstance.py:1087} INFO - Dependencies all met for <TaskInstance: download_uniprot.download_files manual__2022-12-14T21:03:39.311566+00:00 [queued]>
[2022-12-14T18:03:42.181-0300] {taskinstance.py:1087} INFO - Dependencies all met for <TaskInstance: download_uniprot.download_files manual__2022-12-14T21:03:39.311566+00:00 [queued]>
[2022-12-14T18:03:42.182-0300] {taskinstance.py:1283} INFO - 
--------------------------------------------------------------------------------
[2022-12-14T18:03:42.182-0300] {taskinstance.py:1284} INFO - Starting attempt 1 of 1
[2022-12-14T18:03:42.182-0300] {taskinstance.py:1285} INFO - 
--------------------------------------------------------------------------------
[2022-12-14T18:03:42.196-0300] {taskinstance.py:1304} INFO - Executing <Task(PythonOperator): download_files> on 2022-12-14 21:03:39.311566+00:00
[2022-12-14T18:03:42.199-0300] {standard_task_runner.py:55} INFO - Started process 11680 to run task
[2022-12-14T18:03:42.202-0300] {standard_task_runner.py:82} INFO - Running: ['***', 'tasks', 'run', 'download_uniprot', 'download_files', 'manual__2022-12-14T21:03:39.311566+00:00', '--job-id', '3', '--raw', '--subdir', 'DAGS_FOLDER/download_uniprot.py', '--cfg-path', '/tmp/tmp7v13jzec']
[2022-12-14T18:03:42.203-0300] {standard_task_runner.py:83} INFO - Job 3: Subtask download_files
[2022-12-14T18:03:42.277-0300] {task_command.py:389} INFO - Running <TaskInstance: download_uniprot.download_files manual__2022-12-14T21:03:39.311566+00:00 [running]> on host kallo-Ubuntu
[2022-12-14T18:03:42.379-0300] {taskinstance.py:1513} INFO - Exporting the following env vars:
AIRFLOW_CTX_DAG_OWNER=Kallox
AIRFLOW_CTX_DAG_ID=download_uniprot
AIRFLOW_CTX_TASK_ID=download_files
AIRFLOW_CTX_EXECUTION_DATE=2022-12-14T21:03:39.311566+00:00
AIRFLOW_CTX_TRY_NUMBER=1
AIRFLOW_CTX_DAG_RUN_ID=manual__2022-12-14T21:03:39.311566+00:00
[2022-12-14T18:03:42.381-0300] {taskinstance.py:1772} ERROR - Task failed with exception
Traceback (most recent call last):
  File "/home/kallox/anaconda3/envs/airflow/lib/python3.7/site-packages/airflow/operators/python.py", line 175, in execute
    return_value = self.execute_callable()
  File "/home/kallox/anaconda3/envs/airflow/lib/python3.7/site-packages/airflow/operators/python.py", line 192, in execute_callable
    return self.python_callable(*self.op_args, **self.op_kwargs)
  File "/home/kallox/airflow/dags/scripts/uniprot/download.py", line 22, in download
    files = pd.read_csv('./dags/scripts/uniprot/urls.csv')
  File "/home/kallox/anaconda3/envs/airflow/lib/python3.7/site-packages/pandas/util/_decorators.py", line 311, in wrapper
    return func(*args, **kwargs)
  File "/home/kallox/anaconda3/envs/airflow/lib/python3.7/site-packages/pandas/io/parsers/readers.py", line 586, in read_csv
    return _read(filepath_or_buffer, kwds)
  File "/home/kallox/anaconda3/envs/airflow/lib/python3.7/site-packages/pandas/io/parsers/readers.py", line 482, in _read
    parser = TextFileReader(filepath_or_buffer, **kwds)
  File "/home/kallox/anaconda3/envs/airflow/lib/python3.7/site-packages/pandas/io/parsers/readers.py", line 811, in __init__
    self._engine = self._make_engine(self.engine)
  File "/home/kallox/anaconda3/envs/airflow/lib/python3.7/site-packages/pandas/io/parsers/readers.py", line 1040, in _make_engine
    return mapping[engine](self.f, **self.options)  # type: ignore[call-arg]
  File "/home/kallox/anaconda3/envs/airflow/lib/python3.7/site-packages/pandas/io/parsers/c_parser_wrapper.py", line 51, in __init__
    self._open_handles(src, kwds)
  File "/home/kallox/anaconda3/envs/airflow/lib/python3.7/site-packages/pandas/io/parsers/base_parser.py", line 229, in _open_handles
    errors=kwds.get("encoding_errors", "strict"),
  File "/home/kallox/anaconda3/envs/airflow/lib/python3.7/site-packages/pandas/io/common.py", line 707, in get_handle
    newline="",
FileNotFoundError: [Errno 2] No such file or directory: './dags/scripts/uniprot/urls.csv'
[2022-12-14T18:03:42.395-0300] {taskinstance.py:1327} INFO - Marking task as FAILED. dag_id=download_uniprot, task_id=download_files, execution_date=20221214T210339, start_date=20221214T210342, end_date=20221214T210342
[2022-12-14T18:03:42.408-0300] {standard_task_runner.py:105} ERROR - Failed to execute job 3 for task download_files ([Errno 2] No such file or directory: './dags/scripts/uniprot/urls.csv'; 11680)
[2022-12-14T18:03:42.453-0300] {local_task_job.py:159} INFO - Task exited with return code 1
[2022-12-14T18:03:42.488-0300] {taskinstance.py:2582} INFO - 0 downstream tasks scheduled from follow-on schedule check
