[2022-12-20T22:40:20.978-0300] {taskinstance.py:1087} INFO - Dependencies all met for <TaskInstance: download_iedb.download_files manual__2022-12-21T01:40:19.668389+00:00 [queued]>
[2022-12-20T22:40:20.994-0300] {taskinstance.py:1087} INFO - Dependencies all met for <TaskInstance: download_iedb.download_files manual__2022-12-21T01:40:19.668389+00:00 [queued]>
[2022-12-20T22:40:20.994-0300] {taskinstance.py:1283} INFO - 
--------------------------------------------------------------------------------
[2022-12-20T22:40:20.994-0300] {taskinstance.py:1284} INFO - Starting attempt 1 of 1
[2022-12-20T22:40:20.995-0300] {taskinstance.py:1285} INFO - 
--------------------------------------------------------------------------------
[2022-12-20T22:40:21.010-0300] {taskinstance.py:1304} INFO - Executing <Task(PythonOperator): download_files> on 2022-12-21 01:40:19.668389+00:00
[2022-12-20T22:40:21.016-0300] {standard_task_runner.py:55} INFO - Started process 39894 to run task
[2022-12-20T22:40:21.021-0300] {standard_task_runner.py:82} INFO - Running: ['***', 'tasks', 'run', 'download_iedb', 'download_files', 'manual__2022-12-21T01:40:19.668389+00:00', '--job-id', '23', '--raw', '--subdir', 'DAGS_FOLDER/download_iedb.py', '--cfg-path', '/tmp/tmpfmi0c_j3']
[2022-12-20T22:40:21.022-0300] {standard_task_runner.py:83} INFO - Job 23: Subtask download_files
[2022-12-20T22:40:21.099-0300] {task_command.py:389} INFO - Running <TaskInstance: download_iedb.download_files manual__2022-12-21T01:40:19.668389+00:00 [running]> on host kallo-Ubuntu
[2022-12-20T22:40:21.181-0300] {taskinstance.py:1513} INFO - Exporting the following env vars:
AIRFLOW_CTX_DAG_OWNER=Kallox
AIRFLOW_CTX_DAG_ID=download_iedb
AIRFLOW_CTX_TASK_ID=download_files
AIRFLOW_CTX_EXECUTION_DATE=2022-12-21T01:40:19.668389+00:00
AIRFLOW_CTX_TRY_NUMBER=1
AIRFLOW_CTX_DAG_RUN_ID=manual__2022-12-21T01:40:19.668389+00:00
[2022-12-20T22:40:21.182-0300] {taskinstance.py:1772} ERROR - Task failed with exception
Traceback (most recent call last):
  File "/home/kallox/anaconda3/envs/airflow/lib/python3.7/site-packages/airflow/operators/python.py", line 175, in execute
    return_value = self.execute_callable()
  File "/home/kallox/anaconda3/envs/airflow/lib/python3.7/site-packages/airflow/operators/python.py", line 192, in execute_callable
    return self.python_callable(*self.op_args, **self.op_kwargs)
  File "/home/kallox/airflow/dags/scripts/iedb/download.py", line 29, in download
    files = pd.read_csv('./scripts/iedb/urls.csv')
  File "/home/kallox/anaconda3/envs/airflow/lib/python3.7/site-packages/pandas/util/_decorators.py", line 311, in wrapper
    return func(*args, **kwargs)
  File "/home/kallox/anaconda3/envs/airflow/lib/python3.7/site-packages/pandas/io/parsers/readers.py", line 586, in read_csv
    return _read(filepath_or_buffer, kwds)
  File "/home/kallox/anaconda3/envs/airflow/lib/python3.7/site-packages/pandas/io/parsers/readers.py", line 482, in _read
    parser = TextFileReader(filepath_or_buffer, **kwds)
  File "/home/kallox/anaconda3/envs/airflow/lib/python3.7/site-packages/pandas/io/parsers/readers.py", line 811, in __init__
    self._engine = self._make_engine(self.engine)
  File "/home/kallox/anaconda3/envs/airflow/lib/python3.7/site-packages/pandas/io/parsers/readers.py", line 1040, in _make_engine
    return mapping[engine](self.f, **self.options)  # type: ignore[call-arg]
  File "/home/kallox/anaconda3/envs/airflow/lib/python3.7/site-packages/pandas/io/parsers/c_parser_wrapper.py", line 51, in __init__
    self._open_handles(src, kwds)
  File "/home/kallox/anaconda3/envs/airflow/lib/python3.7/site-packages/pandas/io/parsers/base_parser.py", line 229, in _open_handles
    errors=kwds.get("encoding_errors", "strict"),
  File "/home/kallox/anaconda3/envs/airflow/lib/python3.7/site-packages/pandas/io/common.py", line 707, in get_handle
    newline="",
FileNotFoundError: [Errno 2] No such file or directory: './scripts/iedb/urls.csv'
[2022-12-20T22:40:21.197-0300] {taskinstance.py:1327} INFO - Marking task as FAILED. dag_id=download_iedb, task_id=download_files, execution_date=20221221T014019, start_date=20221221T014020, end_date=20221221T014021
[2022-12-20T22:40:21.210-0300] {standard_task_runner.py:105} ERROR - Failed to execute job 23 for task download_files ([Errno 2] No such file or directory: './scripts/iedb/urls.csv'; 39894)
[2022-12-20T22:40:21.231-0300] {local_task_job.py:159} INFO - Task exited with return code 1
[2022-12-20T22:40:21.264-0300] {taskinstance.py:2582} INFO - 0 downstream tasks scheduled from follow-on schedule check
